<?xml version="1.0" encoding="utf-8"?>
<!-- This URDF was automatically created by SolidWorks to URDF Exporter! Originally created by Stephen Brawner (brawner@gmail.com) 
     Commit Version: 1.6.0-4-g7f85cfe  Build Version: 1.6.7995.38578
     For more information, please see http://wiki.ros.org/sw_urdf_exporter -->
<robot
  name="CLOVIS25_URDF_V1">
  <link
    name="base_link_R0_HipsWaist_Yaw">
    <inertial>
      <origin
        xyz="-5.06849795023355E-07 0.00646210878121357 -0.0073561947767718"
        rpy="0 0 0" />
      <mass
        value="0.387437520077022" />
      <inertia
        ixx="0.000602004181066267"
        ixy="-3.93523962007609E-09"
        ixz="8.41311428238355E-09"
        iyy="0.000554663199183165"
        iyz="0.000144231027668739"
        izz="0.000591393422258071" />
    </inertial>
    <visual>
      <origin
        xyz="0 0 0"
        rpy="0 0 0" />
      <geometry>
        <mesh
          filename="package://CLOVIS25_URDF_V1/meshes/base_link_R0_HipsWaist_Yaw.STL" />
      </geometry>
      <material
        name="">
        <color
          rgba="0.752941176470588 0.752941176470588 0.752941176470588 1" />
      </material>
    </visual>
    <collision>
      <origin
        xyz="0 0 0"
        rpy="0 0 0" />
      <geometry>
        <mesh
          filename="package://CLOVIS25_URDF_V1/meshes/base_link_R0_HipsWaist_Yaw.STL" />
      </geometry>
    </collision>
  </link>
  <link
    name="LinkR0_AxisRz_Waist_Yaw">
    <inertial>
      <origin
        xyz="1.46812364462255E-08 0.00792255367963895 0.0328105533698632"
        rpy="0 0 0" />
      <mass
        value="0.0743770113903965" />
      <inertia
        ixx="0.000109844902331301"
        ixy="6.43572843873988E-11"
        ixz="1.80691197514387E-11"
        iyy="5.27744826789088E-05"
        iyz="8.66811215600052E-06"
        izz="6.86185978836167E-05" />
    </inertial>
    <visual>
      <origin
        xyz="0 0 0"
        rpy="0 0 0" />
      <geometry>
        <mesh
          filename="package://CLOVIS25_URDF_V1/meshes/LinkR0_AxisRz_Waist_Yaw.STL" />
      </geometry>
      <material
        name="">
        <color
          rgba="0.752941176470588 0.752941176470588 0.752941176470588 1" />
      </material>
    </visual>
    <collision>
      <origin
        xyz="0 0 0"
        rpy="0 0 0" />
      <geometry>
        <mesh
          filename="package://CLOVIS25_URDF_V1/meshes/LinkR0_AxisRz_Waist_Yaw.STL" />
      </geometry>
    </collision>
  </link>
  <joint
    name="R0_AxisRz_Waist_Yaw"
    type="revolute">
    <origin
      xyz="0 0 0"
      rpy="0 0 0" />
    <parent
      link="base_link_R0_HipsWaist_Yaw" />
    <child
      link="LinkR0_AxisRz_Waist_Yaw" />
    <axis
      xyz="0 0 1" />
    <limit
      lower="-0.611"
      upper="0.611"
      effort="3.66"
      velocity="5.05" />
  </joint>
  <link
    name="Link1_AxisRx_Abs_Roll">
    <inertial>
      <origin
        xyz="-0.000419037666758402 -8.67044488957477E-06 0.00334728947605585"
        rpy="0 0 0" />
      <mass
        value="0.0285702910432507" />
      <inertia
        ixx="7.08725803682833E-06"
        ixy="-2.4583009930953E-09"
        ixz="-4.77409616772989E-08"
        iyy="2.32521875946385E-05"
        iyz="-1.5933209297653E-09"
        izz="2.62164733137173E-05" />
    </inertial>
    <visual>
      <origin
        xyz="0 0 0"
        rpy="0 0 0" />
      <geometry>
        <mesh
          filename="package://CLOVIS25_URDF_V1/meshes/Link1_AxisRx_Abs_Roll.STL" />
      </geometry>
      <material
        name="">
        <color
          rgba="0.698039215686274 0.698039215686274 0.698039215686274 1" />
      </material>
    </visual>
    <collision>
      <origin
        xyz="0 0 0"
        rpy="0 0 0" />
      <geometry>
        <mesh
          filename="package://CLOVIS25_URDF_V1/meshes/Link1_AxisRx_Abs_Roll.STL" />
      </geometry>
    </collision>
  </link>
  <joint
    name="R1_AxisRx_Abs_Roll"
    type="revolute">
    <origin
      xyz="0 0 0.0830000000000002"
      rpy="0 0 1.5707963267949" />
    <parent
      link="LinkR0_AxisRz_Waist_Yaw" />
    <child
      link="Link1_AxisRx_Abs_Roll" />
    <axis
      xyz="-1 0 0" />
    <limit
      lower="-0.524"
      upper="0.524"
      effort="3.66"
      velocity="5.05" />
  </joint>
  <link
    name="Link2_AxisRy_Abs_Pitch">
    <inertial>
      <origin
        xyz="0.0116501815545738 0.000444755823082578 0.0990057387692196"
        rpy="0 0 0" />
      <mass
        value="1.76578960853427" />
      <inertia
        ixx="0.00272833770966601"
        ixy="-2.20261467407053E-07"
        ixz="8.18791957211432E-05"
        iyy="0.00286417267442453"
        iyz="4.10693898067738E-07"
        izz="0.00262213378106293" />
    </inertial>
    <visual>
      <origin
        xyz="0 0 0"
        rpy="0 0 0" />
      <geometry>
        <mesh
          filename="package://CLOVIS25_URDF_V1/meshes/Link2_AxisRy_Abs_Pitch.STL" />
      </geometry>
      <material
        name="">
        <color
          rgba="0.752941176470588 0.752941176470588 0.752941176470588 1" />
      </material>
    </visual>
    <collision>
      <origin
        xyz="0 0 0"
        rpy="0 0 0" />
      <geometry>
        <mesh
          filename="package://CLOVIS25_URDF_V1/meshes/Link2_AxisRy_Abs_Pitch.STL" />
      </geometry>
    </collision>
  </link>
  <joint
    name="R2_AxisRy_Abs_Pitch"
    type="revolute">
    <origin
      xyz="0 0 0"
      rpy="0 0 0" />
    <parent
      link="Link1_AxisRx_Abs_Roll" />
    <child
      link="Link2_AxisRy_Abs_Pitch" />
    <axis
      xyz="0 -1 0" />
    <limit
      lower="-0.689"
      upper="0.785"
      effort="3.66"
      velocity="5.05" />
  </joint>
  <link
    name="Link30_AxisRy_Shoulder_Flexion">
    <inertial>
      <origin
        xyz="-0.00121122065822726 -0.0032503807607366 0.0120544903508713"
        rpy="0 0 0" />
      <mass
        value="0.0372580130703828" />
      <inertia
        ixx="1.59289941290387E-05"
        ixy="-1.20792452999148E-06"
        ixz="-4.7940506523625E-07"
        iyy="1.63933970089758E-05"
        iyz="-8.02786738789989E-07"
        izz="2.03149647590168E-05" />
    </inertial>
    <visual>
      <origin
        xyz="0 0 0"
        rpy="0 0 0" />
      <geometry>
        <mesh
          filename="package://CLOVIS25_URDF_V1/meshes/Link30_AxisRy_Shoulder_Flexion.STL" />
      </geometry>
      <material
        name="">
        <color
          rgba="0.752941176470588 0.752941176470588 0.752941176470588 1" />
      </material>
    </visual>
    <collision>
      <origin
        xyz="0 0 0"
        rpy="0 0 0" />
      <geometry>
        <mesh
          filename="package://CLOVIS25_URDF_V1/meshes/Link30_AxisRy_Shoulder_Flexion.STL" />
      </geometry>
    </collision>
  </link>
  <joint
    name="R30_AxisRy_Shoulder_Flexion"
    type="revolute">
    <origin
      xyz="0.0289259399205682 -0.101367916470833 0.130853241275273"
      rpy="-0.252680255142087 1.30019891167267 -1.5707963267949" />
    <parent
      link="Link2_AxisRy_Abs_Pitch" />
    <child
      link="Link30_AxisRy_Shoulder_Flexion" />
    <axis
      xyz="0 0 1" />
    <limit
      lower="0"
      upper="0"
      effort="0"
      velocity="0" />
  </joint>
  <link
    name="Link31_AxisRz_Shoulder_Rotation">
    <inertial>
      <origin
        xyz="0.0310376632963733 0.0149615998455135 -0.00284843103933211"
        rpy="0 0 0" />
      <mass
        value="0.0306387760752887" />
      <inertia
        ixx="1.91180450287481E-05"
        ixy="-2.81655737035408E-07"
        ixz="8.43328137709066E-07"
        iyy="2.64927352089561E-05"
        iyz="-1.49756484162897E-07"
        izz="1.4496990488765E-05" />
    </inertial>
    <visual>
      <origin
        xyz="0 0 0"
        rpy="0 0 0" />
      <geometry>
        <mesh
          filename="package://CLOVIS25_URDF_V1/meshes/Link31_AxisRz_Shoulder_Rotation.STL" />
      </geometry>
      <material
        name="">
        <color
          rgba="0.752941176470588 0.752941176470588 0.752941176470588 1" />
      </material>
    </visual>
    <collision>
      <origin
        xyz="0 0 0"
        rpy="0 0 0" />
      <geometry>
        <mesh
          filename="package://CLOVIS25_URDF_V1/meshes/Link31_AxisRz_Shoulder_Rotation.STL" />
      </geometry>
    </collision>
  </link>
  <joint
    name="R31_AxisRz_Shoulder_Rotation"
    type="revolute">
    <origin
      xyz="0 0 0.0185"
      rpy="1.57079632679489 -1.31811607165281 -1.57079632679489" />
    <parent
      link="Link30_AxisRy_Shoulder_Flexion" />
    <child
      link="Link31_AxisRz_Shoulder_Rotation" />
    <axis
      xyz="0 0 -1" />
    <limit
      lower="0"
      upper="0"
      effort="0"
      velocity="0" />
  </joint>
  <link
    name="Link32_AxisRx_Shoulder_Abduction">
    <inertial>
      <origin
        xyz="0.0104532597532832 0.062163437137923 -0.0367102436813663"
        rpy="0 0 0" />
      <mass
        value="0.102687647799617" />
      <inertia
        ixx="0.000190390945612112"
        ixy="-3.56957901191034E-06"
        ixz="8.37982644784667E-06"
        iyy="8.9509217629559E-05"
        iyz="1.36359033962321E-05"
        izz="0.000128468014249829" />
    </inertial>
    <visual>
      <origin
        xyz="0 0 0"
        rpy="0 0 0" />
      <geometry>
        <mesh
          filename="package://CLOVIS25_URDF_V1/meshes/Link32_AxisRx_Shoulder_Abduction.STL" />
      </geometry>
      <material
        name="">
        <color
          rgba="0.752941176470588 0.752941176470588 0.752941176470588 1" />
      </material>
    </visual>
    <collision>
      <origin
        xyz="0 0 0"
        rpy="0 0 0" />
      <geometry>
        <mesh
          filename="package://CLOVIS25_URDF_V1/meshes/Link32_AxisRx_Shoulder_Abduction.STL" />
      </geometry>
    </collision>
  </link>
  <joint
    name="R32_AxisRx_Shoulder_Abduction"
    type="revolute">
    <origin
      xyz="0.0399999999999999 0.0350000000000001 -2.70284418109334E-05"
      rpy="-1.5707963267949 0.270597415122226 0" />
    <parent
      link="Link31_AxisRz_Shoulder_Rotation" />
    <child
      link="Link32_AxisRx_Shoulder_Abduction" />
    <axis
      xyz="0 0 -1" />
    <limit
      lower="0"
      upper="0"
      effort="0"
      velocity="0" />
  </joint>
  <link
    name="Link33_AxisRy_Elbow_Flexion">
    <inertial>
      <origin
        xyz="-0.00807277244123869 -0.0218914344069931 2.79389832852361E-07"
        rpy="0 0 0" />
      <mass
        value="0.062525137315617" />
      <inertia
        ixx="2.66478352150102E-05"
        ixy="6.31835903644821E-07"
        ixz="-3.71122215388716E-11"
        iyy="2.90857173843087E-05"
        iyz="-2.29744106491995E-10"
        izz="2.16871210520696E-05" />
    </inertial>
    <visual>
      <origin
        xyz="0 0 0"
        rpy="0 0 0" />
      <geometry>
        <mesh
          filename="package://CLOVIS25_URDF_V1/meshes/Link33_AxisRy_Elbow_Flexion.STL" />
      </geometry>
      <material
        name="">
        <color
          rgba="0.752941176470588 0.752941176470588 0.752941176470588 1" />
      </material>
    </visual>
    <collision>
      <origin
        xyz="0 0 0"
        rpy="0 0 0" />
      <geometry>
        <mesh
          filename="package://CLOVIS25_URDF_V1/meshes/Link33_AxisRy_Elbow_Flexion.STL" />
      </geometry>
    </collision>
  </link>
  <joint
    name="R33_AxisRy_Elbow_Flexion"
    type="revolute">
    <origin
      xyz="0.0113302428061854 0.129505311080098 -0.035"
      rpy="1.5707963267949 0 -1.65806278939461" />
    <parent
      link="Link32_AxisRx_Shoulder_Abduction" />
    <child
      link="Link33_AxisRy_Elbow_Flexion" />
    <axis
      xyz="0 0 -1" />
    <limit
      lower="0"
      upper="0"
      effort="0"
      velocity="0" />
  </joint>
  <link
    name="Link34_AxisRz_Wrist_Rotation">
    <inertial>
      <origin
        xyz="0.000526763744020914 0.000899599310191112 -0.0255225516370474"
        rpy="0 0 0" />
      <mass
        value="0.095705310536798" />
      <inertia
        ixx="5.31202839633425E-05"
        ixy="-5.3221844098925E-08"
        ixz="1.77417951512111E-07"
        iyy="5.30307409762005E-05"
        iyz="1.14726761692781E-06"
        izz="3.79616505903217E-05" />
    </inertial>
    <visual>
      <origin
        xyz="0 0 0"
        rpy="0 0 0" />
      <geometry>
        <mesh
          filename="package://CLOVIS25_URDF_V1/meshes/Link34_AxisRz_Wrist_Rotation.STL" />
      </geometry>
      <material
        name="">
        <color
          rgba="0.752941176470588 0.752941176470588 0.752941176470588 1" />
      </material>
    </visual>
    <collision>
      <origin
        xyz="0 0 0"
        rpy="0 0 0" />
      <geometry>
        <mesh
          filename="package://CLOVIS25_URDF_V1/meshes/Link34_AxisRz_Wrist_Rotation.STL" />
      </geometry>
    </collision>
  </link>
  <joint
    name="R34_AxisRz_Wrist_Rotation"
    type="revolute">
    <origin
      xyz="-0.0399999999999999 -0.019 0"
      rpy="0 1.5707963267949 0" />
    <parent
      link="Link33_AxisRy_Elbow_Flexion" />
    <child
      link="Link34_AxisRz_Wrist_Rotation" />
    <axis
      xyz="0 0 -1" />
    <limit
      lower="0"
      upper="0"
      effort="0"
      velocity="0" />
  </joint>
  <link
    name="Link35_AxisRx_Wrist_Abduction">
    <inertial>
      <origin
        xyz="-0.00813435863366127 -4.05206365901994E-07 -5.46147126134766E-08"
        rpy="0 0 0" />
      <mass
        value="0.0129110778126474" />
      <inertia
        ixx="5.34580369587511E-06"
        ixy="1.03772626656382E-10"
        ixz="6.34307336220814E-11"
        iyy="1.41876387165846E-06"
        iyz="1.77315331995067E-11"
        izz="5.32098561653815E-06" />
    </inertial>
    <visual>
      <origin
        xyz="0 0 0"
        rpy="0 0 0" />
      <geometry>
        <mesh
          filename="package://CLOVIS25_URDF_V1/meshes/Link35_AxisRx_Wrist_Abduction.STL" />
      </geometry>
      <material
        name="">
        <color
          rgba="0.752941176470588 0.752941176470588 0.752941176470588 1" />
      </material>
    </visual>
    <collision>
      <origin
        xyz="0 0 0"
        rpy="0 0 0" />
      <geometry>
        <mesh
          filename="package://CLOVIS25_URDF_V1/meshes/Link35_AxisRx_Wrist_Abduction.STL" />
      </geometry>
    </collision>
  </link>
  <joint
    name="R35_AxisRx_Wrist_Abduction"
    type="revolute">
    <origin
      xyz="0 0 -0.0931377805455123"
      rpy="0 1.5707963267949 0" />
    <parent
      link="Link34_AxisRz_Wrist_Rotation" />
    <child
      link="Link35_AxisRx_Wrist_Abduction" />
    <axis
      xyz="0 0 1" />
    <limit
      lower="0"
      upper="0"
      effort="0"
      velocity="0" />
  </joint>
  <link
    name="Link36_AxisRy_Wrist_Flexion">
    <inertial>
      <origin
        xyz="0.00278270226149457 0.0506978853954537 0.000512408108842817"
        rpy="0 0 0" />
      <mass
        value="0.0948668355736169" />
      <inertia
        ixx="6.39849613428145E-05"
        ixy="-5.73647920852711E-06"
        ixz="3.49414578855144E-06"
        iyy="2.95679718318229E-05"
        iyz="7.83640400248719E-06"
        izz="4.67669259635976E-05" />
    </inertial>
    <visual>
      <origin
        xyz="0 0 0"
        rpy="0 0 0" />
      <geometry>
        <mesh
          filename="package://CLOVIS25_URDF_V1/meshes/Link36_AxisRy_Wrist_Flexion.STL" />
      </geometry>
      <material
        name="">
        <color
          rgba="0.752941176470588 0.752941176470588 0.752941176470588 1" />
      </material>
    </visual>
    <collision>
      <origin
        xyz="0 0 0"
        rpy="0 0 0" />
      <geometry>
        <mesh
          filename="package://CLOVIS25_URDF_V1/meshes/Link36_AxisRy_Wrist_Flexion.STL" />
      </geometry>
    </collision>
  </link>
  <joint
    name="R36_AxisRy_Wrist_Flexion"
    type="revolute">
    <origin
      xyz="0 0 0"
      rpy="-1.5707963267949 -1.48352986419518 0" />
    <parent
      link="Link35_AxisRx_Wrist_Abduction" />
    <child
      link="Link36_AxisRy_Wrist_Flexion" />
    <axis
      xyz="0 0 1" />
    <limit
      lower="0"
      upper="0"
      effort="0"
      velocity="0" />
  </joint>
  <link
    name="Link51_AxisRz_ThumbKnucle_Rotation">
    <inertial>
      <origin
        xyz="-4.91409359870687E-08 -0.000121891601792302 0.00201210065266348"
        rpy="0 0 0" />
      <mass
        value="0.00115968038152584" />
      <inertia
        ixx="4.03439585122942E-08"
        ixy="-2.39268724415707E-13"
        ixz="-3.87054840502819E-14"
        iyy="4.18267857957113E-08"
        iyz="-4.02150632626584E-10"
        izz="1.66744809622269E-08" />
    </inertial>
    <visual>
      <origin
        xyz="0 0 0"
        rpy="0 0 0" />
      <geometry>
        <mesh
          filename="package://CLOVIS25_URDF_V1/meshes/Link51_AxisRz_ThumbKnucle_Rotation.STL" />
      </geometry>
      <material
        name="">
        <color
          rgba="0.752941176470588 0.752941176470588 0.752941176470588 1" />
      </material>
    </visual>
    <collision>
      <origin
        xyz="0 0 0"
        rpy="0 0 0" />
      <geometry>
        <mesh
          filename="package://CLOVIS25_URDF_V1/meshes/Link51_AxisRz_ThumbKnucle_Rotation.STL" />
      </geometry>
    </collision>
  </link>
  <joint
    name="R51_AxisRz_ThumbKnucle_Rotation"
    type="revolute">
    <origin
      xyz="-0.020899 0.0382 0.021786"
      rpy="1.5708 0 0" />
    <parent
      link="Link36_AxisRy_Wrist_Flexion" />
    <child
      link="Link51_AxisRz_ThumbKnucle_Rotation" />
    <axis
      xyz="0 0 -1" />
    <limit
      lower="0"
      upper="0"
      effort="0"
      velocity="0" />
  </joint>
  <link
    name="Link52_AxisRy_ThumbKnucle_Flexion">
    <inertial>
      <origin
        xyz="0.00616866200396443 -0.0146131442688366 -8.87240668712153E-08"
        rpy="0 0 0" />
      <mass
        value="0.00310333576369737" />
      <inertia
        ixx="2.79345952527195E-07"
        ixy="5.45699827270546E-08"
        ixz="1.93583934037853E-12"
        iyy="1.60619700743313E-07"
        iyz="-1.82698794771484E-12"
        izz="2.38435467591377E-07" />
    </inertial>
    <visual>
      <origin
        xyz="0 0 0"
        rpy="0 0 0" />
      <geometry>
        <mesh
          filename="package://CLOVIS25_URDF_V1/meshes/Link52_AxisRy_ThumbKnucle_Flexion.STL" />
      </geometry>
      <material
        name="">
        <color
          rgba="0.752941176470588 0.752941176470588 0.752941176470588 1" />
      </material>
    </visual>
    <collision>
      <origin
        xyz="0 0 0"
        rpy="0 0 0" />
      <geometry>
        <mesh
          filename="package://CLOVIS25_URDF_V1/meshes/Link52_AxisRy_ThumbKnucle_Flexion.STL" />
      </geometry>
    </collision>
  </link>
  <joint
    name="R52_AxisRy_ThumbKnucle_Flexion"
    type="revolute">
    <origin
      xyz="0 0.028971 -0.0077892"
      rpy="3.1416 -1.5708 0" />
    <parent
      link="Link51_AxisRz_ThumbKnucle_Rotation" />
    <child
      link="Link52_AxisRy_ThumbKnucle_Flexion" />
    <axis
      xyz="0 0 1" />
    <limit
      lower="0"
      upper="0"
      effort="0"
      velocity="0" />
  </joint>
  <link
    name="Link53_AxisRy_Thumb_Flexion">
    <inertial>
      <origin
        xyz="7.16902495649374E-05 0.00984633190079666 -0.000109122506526033"
        rpy="0 0 0" />
      <mass
        value="0.0038950256358541" />
      <inertia
        ixx="3.31740758410824E-07"
        ixy="8.52234616085922E-08"
        ixz="-3.03665120916456E-10"
        iyy="1.4896051880238E-07"
        iyz="8.31876939875982E-10"
        izz="3.11286681941713E-07" />
    </inertial>
    <visual>
      <origin
        xyz="0 0 0"
        rpy="0 0 0" />
      <geometry>
        <mesh
          filename="package://CLOVIS25_URDF_V1/meshes/Link53_AxisRy_Thumb_Flexion.STL" />
      </geometry>
      <material
        name="">
        <color
          rgba="0.752941176470588 0.752941176470588 0.752941176470588 1" />
      </material>
    </visual>
    <collision>
      <origin
        xyz="0 0 0"
        rpy="0 0 0" />
      <geometry>
        <mesh
          filename="package://CLOVIS25_URDF_V1/meshes/Link53_AxisRy_Thumb_Flexion.STL" />
      </geometry>
    </collision>
  </link>
  <joint
    name="R53_AxisRy_Thumb_Flexion"
    type="revolute">
    <origin
      xyz="0 0 0"
      rpy="0 0 0" />
    <parent
      link="Link52_AxisRy_ThumbKnucle_Flexion" />
    <child
      link="Link53_AxisRy_Thumb_Flexion" />
    <axis
      xyz="0 0 -1" />
    <limit
      lower="0"
      upper="0"
      effort="0"
      velocity="0" />
  </joint>
  <link
    name="Link54_AxisRx_IndexKnucle_Abduction">
    <inertial>
      <origin
        xyz="0.000121891601791602 4.91409239897211E-08 -0.00201210065265256"
        rpy="0 0 0" />
      <mass
        value="0.00115968038152584" />
      <inertia
        ixx="4.18267857957199E-08"
        ixy="-2.39268722722505E-13"
        ixz="-4.02150632623778E-10"
        iyy="4.03439585123012E-08"
        iyz="-3.87054860001313E-14"
        izz="1.66744809622338E-08" />
    </inertial>
    <visual>
      <origin
        xyz="0 0 0"
        rpy="0 0 0" />
      <geometry>
        <mesh
          filename="package://CLOVIS25_URDF_V1/meshes/Link54_AxisRx_IndexKnucle_Abduction.STL" />
      </geometry>
      <material
        name="">
        <color
          rgba="0.752941176470588 0.752941176470588 0.752941176470588 1" />
      </material>
    </visual>
    <collision>
      <origin
        xyz="0 0 0"
        rpy="0 0 0" />
      <geometry>
        <mesh
          filename="package://CLOVIS25_URDF_V1/meshes/Link54_AxisRx_IndexKnucle_Abduction.STL" />
      </geometry>
    </collision>
  </link>
  <joint
    name="R54_AxisRx_IndexKnucle_Abduction"
    type="revolute">
    <origin
      xyz="0 0.10071 0.03"
      rpy="1.5708 0 -1.5708" />
    <parent
      link="Link36_AxisRy_Wrist_Flexion" />
    <child
      link="Link54_AxisRx_IndexKnucle_Abduction" />
    <axis
      xyz="0 0 -1" />
    <limit
      lower="0"
      upper="0"
      effort="0"
      velocity="0" />
  </joint>
  <link
    name="Link55_AxisRy_IndexKnucle_Flexion">
    <inertial>
      <origin
        xyz="-0.00211406335375972 0.0145062489951216 -4.40290241071617E-09"
        rpy="0 0 0" />
      <mass
        value="0.00305079596232099" />
      <inertia
        ixx="2.87529730754127E-07"
        ixy="-1.55515958091936E-08"
        ixz="-1.24036019437251E-13"
        iyy="1.38377543503246E-07"
        iyz="-3.76599756774459E-13"
        izz="2.29166032829361E-07" />
    </inertial>
    <visual>
      <origin
        xyz="0 0 0"
        rpy="0 0 0" />
      <geometry>
        <mesh
          filename="package://CLOVIS25_URDF_V1/meshes/Link55_AxisRy_IndexKnucle_Flexion.STL" />
      </geometry>
      <material
        name="">
        <color
          rgba="0.752941176470588 0.752941176470588 0.752941176470588 1" />
      </material>
    </visual>
    <collision>
      <origin
        xyz="0 0 0"
        rpy="0 0 0" />
      <geometry>
        <mesh
          filename="package://CLOVIS25_URDF_V1/meshes/Link55_AxisRy_IndexKnucle_Flexion.STL" />
      </geometry>
    </collision>
  </link>
  <joint
    name="R55_AxisRy_IndexKnucle_Flexion"
    type="revolute">
    <origin
      xyz="0 0 0"
      rpy="1.5708 -1.5708 0" />
    <parent
      link="Link54_AxisRx_IndexKnucle_Abduction" />
    <child
      link="Link55_AxisRy_IndexKnucle_Flexion" />
    <axis
      xyz="0 0 -1" />
    <limit
      lower="0"
      upper="0"
      effort="0"
      velocity="0" />
  </joint>
  <link
    name="Link56_AxisRy_IndexMiddle_Flexion">
    <inertial>
      <origin
        xyz="0.00240152083457901 0.00654385041932926 -7.78004879410724E-05"
        rpy="0 0 0" />
      <mass
        value="0.00237461021631888" />
      <inertia
        ixx="1.93784109250359E-07"
        ixy="1.60821542165139E-08"
        ixz="7.95861715001983E-11"
        iyy="9.31756219047182E-08"
        iyz="3.55124367944453E-10"
        izz="1.51786468172031E-07" />
    </inertial>
    <visual>
      <origin
        xyz="0 0 0"
        rpy="0 0 0" />
      <geometry>
        <mesh
          filename="package://CLOVIS25_URDF_V1/meshes/Link56_AxisRy_IndexMiddle_Flexion.STL" />
      </geometry>
      <material
        name="">
        <color
          rgba="0.752941176470588 0.752941176470588 0.752941176470588 1" />
      </material>
    </visual>
    <collision>
      <origin
        xyz="0 0 0"
        rpy="0 0 0" />
      <geometry>
        <mesh
          filename="package://CLOVIS25_URDF_V1/meshes/Link56_AxisRy_IndexMiddle_Flexion.STL" />
      </geometry>
    </collision>
  </link>
  <joint
    name="R56_AxisRy_IndexMiddle_Flexion"
    type="revolute">
    <origin
      xyz="0 0.0300000000000013 0"
      rpy="-3.14159265358979 0 3.14159265358979" />
    <parent
      link="Link55_AxisRy_IndexKnucle_Flexion" />
    <child
      link="Link56_AxisRy_IndexMiddle_Flexion" />
    <axis
      xyz="0 0 -1" />
    <limit
      lower="0"
      upper="0"
      effort="0"
      velocity="0" />
  </joint>
  <link
    name="Link57_AxisRy_IndexTip_Flexion">
    <inertial>
      <origin
        xyz="-0.00555116931160246 0.00681823871642395 -2.21893248580907E-06"
        rpy="0 0 0" />
      <mass
        value="0.00253828371370101" />
      <inertia
        ixx="1.28437698390913E-07"
        ixy="2.5802165942452E-08"
        ixz="7.27690086487842E-12"
        iyy="8.57012975056659E-08"
        iyz="-6.31363709014403E-11"
        izz="1.10632726364158E-07" />
    </inertial>
    <visual>
      <origin
        xyz="0 0 0"
        rpy="0 0 0" />
      <geometry>
        <mesh
          filename="package://CLOVIS25_URDF_V1/meshes/Link57_AxisRy_IndexTip_Flexion.STL" />
      </geometry>
      <material
        name="">
        <color
          rgba="0.752941176470588 0.752941176470588 0.752941176470588 1" />
      </material>
    </visual>
    <collision>
      <origin
        xyz="0 0 0"
        rpy="0 0 0" />
      <geometry>
        <mesh
          filename="package://CLOVIS25_URDF_V1/meshes/Link57_AxisRy_IndexTip_Flexion.STL" />
      </geometry>
    </collision>
  </link>
  <joint
    name="R57_AxisRy_IndexTip_Flexion"
    type="revolute">
    <origin
      xyz="-0.000938526804101725 0.0189768060389028 -0.000100000000000017"
      rpy="0 0 0" />
    <parent
      link="Link56_AxisRy_IndexMiddle_Flexion" />
    <child
      link="Link57_AxisRy_IndexTip_Flexion" />
    <axis
      xyz="0 0 -1" />
    <limit
      lower="0"
      upper="0"
      effort="0"
      velocity="0" />
  </joint>
  <link
    name="Link58_AxisRy_MiddleFingerKnucle_Flexion">
    <inertial>
      <origin
        xyz="-0.00211406335375619 0.0145062489951234 -4.40290519668207E-09"
        rpy="0 0 0" />
      <mass
        value="0.00305079596232101" />
      <inertia
        ixx="2.87529730754123E-07"
        ixy="-1.55515958092051E-08"
        ixz="-1.24036019297732E-13"
        iyy="1.38377543503299E-07"
        iyz="-3.76599757395791E-13"
        izz="2.29166032829408E-07" />
    </inertial>
    <visual>
      <origin
        xyz="0 0 0"
        rpy="0 0 0" />
      <geometry>
        <mesh
          filename="package://CLOVIS25_URDF_V1/meshes/Link58_AxisRy_MiddleFingerKnucle_Flexion.STL" />
      </geometry>
      <material
        name="">
        <color
          rgba="0.752941176470588 0.752941176470588 0.752941176470588 1" />
      </material>
    </visual>
    <collision>
      <origin
        xyz="0 0 0"
        rpy="0 0 0" />
      <geometry>
        <mesh
          filename="package://CLOVIS25_URDF_V1/meshes/Link58_AxisRy_MiddleFingerKnucle_Flexion.STL" />
      </geometry>
    </collision>
  </link>
  <joint
    name="R58_AxisRy_MiddleFingerKnucle_Flexion"
    type="revolute">
    <origin
      xyz="0 0.0957999999999998 0.0121"
      rpy="3.14159265358979 0 -3.14159265358979" />
    <parent
      link="Link36_AxisRy_Wrist_Flexion" />
    <child
      link="Link58_AxisRy_MiddleFingerKnucle_Flexion" />
    <axis
      xyz="0 0 -1" />
    <limit
      lower="0"
      upper="0"
      effort="0"
      velocity="0" />
  </joint>
  <link
    name="Link59_AxisRy_MiddleFingerMiddle_Flexion">
    <inertial>
      <origin
        xyz="0.00240152083459544 0.00654385041930861 -7.78004879377417E-05"
        rpy="0 0 0" />
      <mass
        value="0.00237461021631887" />
      <inertia
        ixx="1.93784109250358E-07"
        ixy="1.60821542165148E-08"
        ixz="7.95861715003256E-11"
        iyy="9.31756219047172E-08"
        iyz="3.55124367944247E-10"
        izz="1.51786468172029E-07" />
    </inertial>
    <visual>
      <origin
        xyz="0 0 0"
        rpy="0 0 0" />
      <geometry>
        <mesh
          filename="package://CLOVIS25_URDF_V1/meshes/Link59_AxisRy_MiddleFingerMiddle_Flexion.STL" />
      </geometry>
      <material
        name="">
        <color
          rgba="0.752941176470588 0.752941176470588 0.752941176470588 1" />
      </material>
    </visual>
    <collision>
      <origin
        xyz="0 0 0"
        rpy="0 0 0" />
      <geometry>
        <mesh
          filename="package://CLOVIS25_URDF_V1/meshes/Link59_AxisRy_MiddleFingerMiddle_Flexion.STL" />
      </geometry>
    </collision>
  </link>
  <joint
    name="R59_AxisRy_MiddleFingerMiddle_Flexion"
    type="revolute">
    <origin
      xyz="0 0.0300000000000018 -0.000100000000004839"
      rpy="-3.14159265358979 0 -3.14159265358979" />
    <parent
      link="Link58_AxisRy_MiddleFingerKnucle_Flexion" />
    <child
      link="Link59_AxisRy_MiddleFingerMiddle_Flexion" />
    <axis
      xyz="0 0 -1" />
    <limit
      lower="0"
      upper="0"
      effort="0"
      velocity="0" />
  </joint>
  <link
    name="Link71_AxisRy_MiddleFingerTip_Flexion">
    <inertial>
      <origin
        xyz="-0.00555116931157984 0.00681823871639733 -2.21893248081306E-06"
        rpy="0 0 0" />
      <mass
        value="0.00253828371370102" />
      <inertia
        ixx="1.28437698390917E-07"
        ixy="2.58021659424504E-08"
        ixz="7.27690086485764E-12"
        iyy="8.57012975056682E-08"
        iyz="-6.31363709015149E-11"
        izz="1.10632726364164E-07" />
    </inertial>
    <visual>
      <origin
        xyz="0 0 0"
        rpy="0 0 0" />
      <geometry>
        <mesh
          filename="package://CLOVIS25_URDF_V1/meshes/Link71_AxisRy_MiddleFingerTip_Flexion.STL" />
      </geometry>
      <material
        name="">
        <color
          rgba="0.752941176470588 0.752941176470588 0.752941176470588 1" />
      </material>
    </visual>
    <collision>
      <origin
        xyz="0 0 0"
        rpy="0 0 0" />
      <geometry>
        <mesh
          filename="package://CLOVIS25_URDF_V1/meshes/Link71_AxisRy_MiddleFingerTip_Flexion.STL" />
      </geometry>
    </collision>
  </link>
  <joint
    name="R71_AxisRy_MiddleFingerTip_Flexion"
    type="revolute">
    <origin
      xyz="-0.000938526804097312 0.0189768060388983 -0.000100000000004839"
      rpy="0 0 0" />
    <parent
      link="Link59_AxisRy_MiddleFingerMiddle_Flexion" />
    <child
      link="Link71_AxisRy_MiddleFingerTip_Flexion" />
    <axis
      xyz="0 0 -1" />
    <limit
      lower="0"
      upper="0"
      effort="0"
      velocity="0" />
  </joint>
  <link
    name="Link72_AxisRy_PinkyKnucle_Flexion">
    <inertial>
      <origin
        xyz="-0.00211406335375963 0.0145062489951217 -0.00900000440290133"
        rpy="0 0 0" />
      <mass
        value="0.00610159192464204" />
      <inertia
        ixx="5.7505946150826E-07"
        ixy="-3.110319161842E-08"
        ixz="-2.48072038631475E-13"
        iyy="2.76755087006631E-07"
        iyz="-7.53199513478042E-13"
        izz="4.58332065658862E-07" />
    </inertial>
    <visual>
      <origin
        xyz="0 0 0"
        rpy="0 0 0" />
      <geometry>
        <mesh
          filename="package://CLOVIS25_URDF_V1/meshes/Link72_AxisRy_PinkyKnucle_Flexion.STL" />
      </geometry>
      <material
        name="">
        <color
          rgba="0.752941176470588 0.752941176470588 0.752941176470588 1" />
      </material>
    </visual>
    <collision>
      <origin
        xyz="0 0 0"
        rpy="0 0 0" />
      <geometry>
        <mesh
          filename="package://CLOVIS25_URDF_V1/meshes/Link72_AxisRy_PinkyKnucle_Flexion.STL" />
      </geometry>
    </collision>
  </link>
  <joint
    name="R72_AxisRy_PinkyKnucle_Flexion"
    type="revolute">
    <origin
      xyz="0 0.0957999999999998 -0.0238999999999999"
      rpy="3.14159265358979 0 -3.14159265358979" />
    <parent
      link="Link36_AxisRy_Wrist_Flexion" />
    <child
      link="Link72_AxisRy_PinkyKnucle_Flexion" />
    <axis
      xyz="0 0 1" />
    <limit
      lower="0"
      upper="0"
      effort="0"
      velocity="0" />
  </joint>
  <link
    name="Link73_AxisRy_PinkyMiddle_Flexion">
    <inertial>
      <origin
        xyz="0.00240152083459458 0.00654385041930952 0.00892219951206391"
        rpy="0 0 0" />
      <mass
        value="0.00474922043263774" />
      <inertia
        ixx="3.87568218500717E-07"
        ixy="3.21643084330278E-08"
        ixz="1.59172343000489E-10"
        iyy="1.86351243809441E-07"
        iyz="7.10248735888812E-10"
        izz="3.03572936344066E-07" />
    </inertial>
    <visual>
      <origin
        xyz="0 0 0"
        rpy="0 0 0" />
      <geometry>
        <mesh
          filename="package://CLOVIS25_URDF_V1/meshes/Link73_AxisRy_PinkyMiddle_Flexion.STL" />
      </geometry>
      <material
        name="">
        <color
          rgba="0.752941176470588 0.752941176470588 0.752941176470588 1" />
      </material>
    </visual>
    <collision>
      <origin
        xyz="0 0 0"
        rpy="0 0 0" />
      <geometry>
        <mesh
          filename="package://CLOVIS25_URDF_V1/meshes/Link73_AxisRy_PinkyMiddle_Flexion.STL" />
      </geometry>
    </collision>
  </link>
  <joint
    name="R73_AxisRy_PinkyMiddle_Flexion"
    type="revolute">
    <origin
      xyz="0 0.0300000000000018 -0.000100000000000102"
      rpy="3.14159265358979 0 -3.14159265358979" />
    <parent
      link="Link72_AxisRy_PinkyKnucle_Flexion" />
    <child
      link="Link73_AxisRy_PinkyMiddle_Flexion" />
    <axis
      xyz="0 0 -1" />
    <limit
      lower="0"
      upper="0"
      effort="0"
      velocity="0" />
  </joint>
  <link
    name="Link74_AxisRy_PinkyTip_Flexion">
    <inertial>
      <origin
        xyz="-0.00555116931158159 0.00681823871640067 0.0089977810675173"
        rpy="0 0 0" />
      <mass
        value="0.00507656742740203" />
      <inertia
        ixx="2.56875396781832E-07"
        ixy="5.16043318849009E-08"
        ixz="1.45538017299456E-11"
        iyy="1.71402595011333E-07"
        iyz="-1.26272741803136E-10"
        izz="2.21265452728323E-07" />
    </inertial>
    <visual>
      <origin
        xyz="0 0 0"
        rpy="0 0 0" />
      <geometry>
        <mesh
          filename="package://CLOVIS25_URDF_V1/meshes/Link74_AxisRy_PinkyTip_Flexion.STL" />
      </geometry>
      <material
        name="">
        <color
          rgba="0.752941176470588 0.752941176470588 0.752941176470588 1" />
      </material>
    </visual>
    <collision>
      <origin
        xyz="0 0 0"
        rpy="0 0 0" />
      <geometry>
        <mesh
          filename="package://CLOVIS25_URDF_V1/meshes/Link74_AxisRy_PinkyTip_Flexion.STL" />
      </geometry>
    </collision>
  </link>
  <joint
    name="R74_AxisRy_PinkyTip_Flexion"
    type="revolute">
    <origin
      xyz="-0.000938526804098255 0.0189768060388994 -0.000100000000000005"
      rpy="0 0 0" />
    <parent
      link="Link73_AxisRy_PinkyMiddle_Flexion" />
    <child
      link="Link74_AxisRy_PinkyTip_Flexion" />
    <axis
      xyz="0 0 -1" />
    <limit
      lower="0"
      upper="0"
      effort="0"
      velocity="0" />
  </joint>
  <link
    name="Link40_AxisRy_Shoulder_Flexion">
    <inertial>
      <origin
        xyz="-0.00121123558651465 -0.0032505255283299 -0.0120546201899155"
        rpy="0 0 0" />
      <mass
        value="0.0372585040292266" />
      <inertia
        ixx="1.59292439557234E-05"
        ixy="-1.20796833868441E-06"
        ixz="4.79452740015118E-07"
        iyy="1.63936933583613E-05"
        iyz="8.02800974683708E-07"
        izz="2.0315299924828E-05" />
    </inertial>
    <visual>
      <origin
        xyz="0 0 0"
        rpy="0 0 0" />
      <geometry>
        <mesh
          filename="package://CLOVIS25_URDF_V1/meshes/Link40_AxisRy_Shoulder_Flexion.STL" />
      </geometry>
      <material
        name="">
        <color
          rgba="0.752941176470588 0.752941176470588 0.752941176470588 1" />
      </material>
    </visual>
    <collision>
      <origin
        xyz="0 0 0"
        rpy="0 0 0" />
      <geometry>
        <mesh
          filename="package://CLOVIS25_URDF_V1/meshes/Link40_AxisRy_Shoulder_Flexion.STL" />
      </geometry>
    </collision>
  </link>
  <joint
    name="R40_AxisRy_Shoulder_Flexion"
    type="revolute">
    <origin
      xyz="0.0289259399205682 0.101367916470833 0.130853241275273"
      rpy="-2.88891239844771 1.30019891167267 1.57079632679489" />
    <parent
      link="Link2_AxisRy_Abs_Pitch" />
    <child
      link="Link40_AxisRy_Shoulder_Flexion" />
    <axis
      xyz="0 0 1" />
    <limit
      lower="0"
      upper="0"
      effort="0"
      velocity="0" />
  </joint>
  <link
    name="Link41_AxisRz_Shoulder_Rotation">
    <inertial>
      <origin
        xyz="-0.031037590317066 0.0149616403812063 -0.00284732124355624"
        rpy="0 0 0" />
      <mass
        value="0.0306386900120499" />
      <inertia
        ixx="1.91180620203453E-05"
        ixy="2.81663109524513E-07"
        ixz="-8.4319494731703E-07"
        iyy="2.64926204617935E-05"
        iyz="-1.49808930781168E-07"
        izz="1.44968161981896E-05" />
    </inertial>
    <visual>
      <origin
        xyz="0 0 0"
        rpy="0 0 0" />
      <geometry>
        <mesh
          filename="package://CLOVIS25_URDF_V1/meshes/Link41_AxisRz_Shoulder_Rotation.STL" />
      </geometry>
      <material
        name="">
        <color
          rgba="0.752941176470588 0.752941176470588 0.752941176470588 1" />
      </material>
    </visual>
    <collision>
      <origin
        xyz="0 0 0"
        rpy="0 0 0" />
      <geometry>
        <mesh
          filename="package://CLOVIS25_URDF_V1/meshes/Link41_AxisRz_Shoulder_Rotation.STL" />
      </geometry>
    </collision>
  </link>
  <joint
    name="R41_AxisRz_Shoulder_Rotation"
    type="revolute">
    <origin
      xyz="0 0 -0.0185"
      rpy="-1.5707963267949 -1.31811607165281 1.5707963267949" />
    <parent
      link="Link40_AxisRy_Shoulder_Flexion" />
    <child
      link="Link41_AxisRz_Shoulder_Rotation" />
    <axis
      xyz="0 0 -1" />
    <limit
      lower="0"
      upper="0"
      effort="0"
      velocity="0" />
  </joint>
  <link
    name="Link42_AxisRx_Shoulder_Abduction">
    <inertial>
      <origin
        xyz="-0.0104533722346798 0.0621641528020339 -0.0367098346254363"
        rpy="0 0 0" />
      <mass
        value="0.102684755235716" />
      <inertia
        ixx="0.000190384776496695"
        ixy="3.5698526961541E-06"
        ixz="-8.3801879126661E-06"
        iyy="8.95074855432801E-05"
        iyz="1.36363520295981E-05"
        izz="0.000128462975444537" />
    </inertial>
    <visual>
      <origin
        xyz="0 0 0"
        rpy="0 0 0" />
      <geometry>
        <mesh
          filename="package://CLOVIS25_URDF_V1/meshes/Link42_AxisRx_Shoulder_Abduction.STL" />
      </geometry>
      <material
        name="">
        <color
          rgba="0.752941176470588 0.752941176470588 0.752941176470588 1" />
      </material>
    </visual>
    <collision>
      <origin
        xyz="0 0 0"
        rpy="0 0 0" />
      <geometry>
        <mesh
          filename="package://CLOVIS25_URDF_V1/meshes/Link42_AxisRx_Shoulder_Abduction.STL" />
      </geometry>
    </collision>
  </link>
  <joint
    name="R42_AxisRx_Shoulder_Abduction"
    type="revolute">
    <origin
      xyz="-0.0400000000000001 0.0349999999999999 0"
      rpy="-1.5707963267949 -0.270597415122226 0" />
    <parent
      link="Link41_AxisRz_Shoulder_Rotation" />
    <child
      link="Link42_AxisRx_Shoulder_Abduction" />
    <axis
      xyz="0 0 -1" />
    <limit
      lower="0"
      upper="0"
      effort="0"
      velocity="0" />
  </joint>
  <link
    name="Link43_AxisRy_Elbow_Flexion">
    <inertial>
      <origin
        xyz="-0.00807276875151355 -0.0218914502303467 3.10306755596512E-07"
        rpy="0 0 0" />
      <mass
        value="0.0625250264832972" />
      <inertia
        ixx="2.66478001692804E-05"
        ixy="6.31836851327582E-07"
        ixz="-1.39712764303306E-11"
        iyy="2.90856880879152E-05"
        iyz="-2.34248523832614E-10"
        izz="2.16871103133531E-05" />
    </inertial>
    <visual>
      <origin
        xyz="0 0 0"
        rpy="0 0 0" />
      <geometry>
        <mesh
          filename="package://CLOVIS25_URDF_V1/meshes/Link43_AxisRy_Elbow_Flexion.STL" />
      </geometry>
      <material
        name="">
        <color
          rgba="0.752941176470588 0.752941176470588 0.752941176470588 1" />
      </material>
    </visual>
    <collision>
      <origin
        xyz="0 0 0"
        rpy="0 0 0" />
      <geometry>
        <mesh
          filename="package://CLOVIS25_URDF_V1/meshes/Link43_AxisRy_Elbow_Flexion.STL" />
      </geometry>
    </collision>
  </link>
  <joint
    name="R43_AxisRy_Elbow_Flexion"
    type="revolute">
    <origin
      xyz="-0.0113302416132193 0.129505311184469 -0.035"
      rpy="1.5707963267949 0 -1.48352986419519" />
    <parent
      link="Link42_AxisRx_Shoulder_Abduction" />
    <child
      link="Link43_AxisRy_Elbow_Flexion" />
    <axis
      xyz="0 0 1" />
    <limit
      lower="0"
      upper="0"
      effort="0"
      velocity="0" />
  </joint>
  <link
    name="Link44_AxisRz_Wrist_Rotation">
    <inertial>
      <origin
        xyz="-0.00052013571762774 0.000899444805753595 -0.0257687217825778"
        rpy="0 0 0" />
      <mass
        value="0.0957043837946212" />
      <inertia
        ixx="5.31198213772158E-05"
        ixy="4.22873938637792E-08"
        ixz="-1.80532675917162E-07"
        iyy="5.30300162858389E-05"
        iyz="1.14738316178831E-06"
        izz="3.79612077150448E-05" />
    </inertial>
    <visual>
      <origin
        xyz="0 0 0"
        rpy="0 0 0" />
      <geometry>
        <mesh
          filename="package://CLOVIS25_URDF_V1/meshes/Link44_AxisRz_Wrist_Rotation.STL" />
      </geometry>
      <material
        name="">
        <color
          rgba="0.752941176470588 0.752941176470588 0.752941176470588 1" />
      </material>
    </visual>
    <collision>
      <origin
        xyz="0 0 0"
        rpy="0 0 0" />
      <geometry>
        <mesh
          filename="package://CLOVIS25_URDF_V1/meshes/Link44_AxisRz_Wrist_Rotation.STL" />
      </geometry>
    </collision>
  </link>
  <joint
    name="R44_AxisRz_Wrist_Rotation"
    type="revolute">
    <origin
      xyz="-0.0399999999999999 -0.019 0"
      rpy="-1.57823976718433 1.57079631189374 -1.57823976718433" />
    <parent
      link="Link43_AxisRy_Elbow_Flexion" />
    <child
      link="Link44_AxisRz_Wrist_Rotation" />
    <axis
      xyz="0 0 -1" />
    <limit
      lower="0"
      upper="0"
      effort="0"
      velocity="0" />
  </joint>
  <link
    name="Link45_AxisRx_Wrist_Abduction">
    <inertial>
      <origin
        xyz="-0.00813435863366179 4.05206361997132E-07 5.46147071178726E-08"
        rpy="0 0 0" />
      <mass
        value="0.0129110778126473" />
      <inertia
        ixx="5.34580369587507E-06"
        ixy="-1.03772626656523E-10"
        ixz="-6.34307336185874E-11"
        iyy="1.41876387165847E-06"
        iyz="1.77315331876994E-11"
        izz="5.32098561653811E-06" />
    </inertial>
    <visual>
      <origin
        xyz="0 0 0"
        rpy="0 0 0" />
      <geometry>
        <mesh
          filename="package://CLOVIS25_URDF_V1/meshes/Link45_AxisRx_Wrist_Abduction.STL" />
      </geometry>
      <material
        name="">
        <color
          rgba="0.752941176470588 0.752941176470588 0.752941176470588 1" />
      </material>
    </visual>
    <collision>
      <origin
        xyz="0 0 0"
        rpy="0 0 0" />
      <geometry>
        <mesh
          filename="package://CLOVIS25_URDF_V1/meshes/Link45_AxisRx_Wrist_Abduction.STL" />
      </geometry>
    </collision>
  </link>
  <joint
    name="R45_AxisRx_Wrist_Abduction"
    type="revolute">
    <origin
      xyz="0 0 -0.0935"
      rpy="0 1.5707963267949 0" />
    <parent
      link="Link44_AxisRz_Wrist_Rotation" />
    <child
      link="Link45_AxisRx_Wrist_Abduction" />
    <axis
      xyz="0 0 -1" />
    <limit
      lower="0"
      upper="0"
      effort="0"
      velocity="0" />
  </joint>
  <link
    name="Link46_AxisRy_Wrist_Flexion">
    <inertial>
      <origin
        xyz="0.00278267075384758 0.0506979479143743 -0.000514721850256944"
        rpy="0 0 0" />
      <mass
        value="0.0948671737461925" />
      <inertia
        ixx="6.39852654912567E-05"
        ixy="-5.73654124478472E-06"
        ixz="-3.49417172570608E-06"
        iyy="2.95680935571864E-05"
        iyz="-7.83632804526931E-06"
        izz="4.67672378979348E-05" />
    </inertial>
    <visual>
      <origin
        xyz="0 0 0"
        rpy="0 0 0" />
      <geometry>
        <mesh
          filename="package://CLOVIS25_URDF_V1/meshes/Link46_AxisRy_Wrist_Flexion.STL" />
      </geometry>
      <material
        name="">
        <color
          rgba="0.752941176470588 0.752941176470588 0.752941176470588 1" />
      </material>
    </visual>
    <collision>
      <origin
        xyz="0 0 0"
        rpy="0 0 0" />
      <geometry>
        <mesh
          filename="package://CLOVIS25_URDF_V1/meshes/Link46_AxisRy_Wrist_Flexion.STL" />
      </geometry>
    </collision>
  </link>
  <joint
    name="R46_AxisRy_Wrist_Flexion"
    type="revolute">
    <origin
      xyz="0 0 0"
      rpy="1.5707963267949 1.48352986419519 0" />
    <parent
      link="Link45_AxisRx_Wrist_Abduction" />
    <child
      link="Link46_AxisRy_Wrist_Flexion" />
    <axis
      xyz="0 0 -1" />
    <limit
      lower="0"
      upper="0"
      effort="0"
      velocity="0" />
  </joint>
  <link
    name="Link61_AxisRz_ThumbKnucle_Rotation">
    <inertial>
      <origin
        xyz="4.91409245517715E-08 -0.000121891601797798 -0.00201210065266588"
        rpy="0 0 0" />
      <mass
        value="0.00115968038152584" />
      <inertia
        ixx="4.03439585123012E-08"
        ixy="2.39268724517135E-13"
        ixz="-3.87054840162565E-14"
        iyy="4.18267857957213E-08"
        iyz="4.02150632623847E-10"
        izz="1.66744809622366E-08" />
    </inertial>
    <visual>
      <origin
        xyz="0 0 0"
        rpy="0 0 0" />
      <geometry>
        <mesh
          filename="package://CLOVIS25_URDF_V1/meshes/Link61_AxisRz_ThumbKnucle_Rotation.STL" />
      </geometry>
      <material
        name="">
        <color
          rgba="0.752941176470588 0.752941176470588 0.752941176470588 1" />
      </material>
    </visual>
    <collision>
      <origin
        xyz="0 0 0"
        rpy="0 0 0" />
      <geometry>
        <mesh
          filename="package://CLOVIS25_URDF_V1/meshes/Link61_AxisRz_ThumbKnucle_Rotation.STL" />
      </geometry>
    </collision>
  </link>
  <joint
    name="R61_AxisRz_ThumbKnucle_Rotation"
    type="revolute">
    <origin
      xyz="-0.0208992160414363 0.0381999999999993 -0.0217863192850378"
      rpy="-1.5707963267949 0 0" />
    <parent
      link="Link46_AxisRy_Wrist_Flexion" />
    <child
      link="Link61_AxisRz_ThumbKnucle_Rotation" />
    <axis
      xyz="0 0 -1" />
    <limit
      lower="0"
      upper="0"
      effort="0"
      velocity="0" />
  </joint>
  <link
    name="Link62_AxisRy_ThumbKnucle_Flexion">
    <inertial>
      <origin
        xyz="-0.00162052317270528 0.0143580240590544 -8.87240710345516E-08"
        rpy="0 0 0" />
      <mass
        value="0.00310333576369737" />
      <inertia
        ixx="2.79345952527195E-07"
        ixy="5.4569982727058E-08"
        ixz="1.93583934081574E-12"
        iyy="1.60619700743318E-07"
        iyz="-1.82698794802248E-12"
        izz="2.38435467591382E-07" />
    </inertial>
    <visual>
      <origin
        xyz="0 0 0"
        rpy="0 0 0" />
      <geometry>
        <mesh
          filename="package://CLOVIS25_URDF_V1/meshes/Link62_AxisRy_ThumbKnucle_Flexion.STL" />
      </geometry>
      <material
        name="">
        <color
          rgba="0.752941176470588 0.752941176470588 0.752941176470588 1" />
      </material>
    </visual>
    <collision>
      <origin
        xyz="0 0 0"
        rpy="0 0 0" />
      <geometry>
        <mesh
          filename="package://CLOVIS25_URDF_V1/meshes/Link62_AxisRy_ThumbKnucle_Flexion.STL" />
      </geometry>
    </collision>
  </link>
  <joint
    name="R62_AxisRy_ThumbKnucle_Flexion"
    type="revolute">
    <origin
      xyz="0 0 0"
      rpy="0 1.5707963267949 0" />
    <parent
      link="Link61_AxisRz_ThumbKnucle_Rotation" />
    <child
      link="Link62_AxisRy_ThumbKnucle_Flexion" />
    <axis
      xyz="0 0 1" />
    <limit
      lower="0"
      upper="0"
      effort="0"
      velocity="0" />
  </joint>
  <link
    name="Link63_AxisRy_Thumb_Flexion">
    <inertial>
      <origin
        xyz="7.1690249570544E-05 0.00984633190078806 -0.000109122506530196"
        rpy="0 0 0" />
      <mass
        value="0.00389502563585409" />
      <inertia
        ixx="3.31740758410828E-07"
        ixy="8.5223461608592E-08"
        ixz="-3.03665120916611E-10"
        iyy="1.48960518802381E-07"
        iyz="8.31876939876062E-10"
        izz="3.11286681941716E-07" />
    </inertial>
    <visual>
      <origin
        xyz="0 0 0"
        rpy="0 0 0" />
      <geometry>
        <mesh
          filename="package://CLOVIS25_URDF_V1/meshes/Link63_AxisRy_Thumb_Flexion.STL" />
      </geometry>
      <material
        name="">
        <color
          rgba="0.752941176470588 0.752941176470588 0.752941176470588 1" />
      </material>
    </visual>
    <collision>
      <origin
        xyz="0 0 0"
        rpy="0 0 0" />
      <geometry>
        <mesh
          filename="package://CLOVIS25_URDF_V1/meshes/Link63_AxisRy_Thumb_Flexion.STL" />
      </geometry>
    </collision>
  </link>
  <joint
    name="R63_AxisRy_Thumb_Flexion"
    type="revolute">
    <origin
      xyz="-0.00778918517667519 0.0289711683278997 9.9999999999989E-05"
      rpy="0 0 0" />
    <parent
      link="Link62_AxisRy_ThumbKnucle_Flexion" />
    <child
      link="Link63_AxisRy_Thumb_Flexion" />
    <axis
      xyz="0 0 -1" />
    <limit
      lower="0"
      upper="0"
      effort="0"
      velocity="0" />
  </joint>
  <link
    name="Link64_AxisRx_IndexKnucle_Abduction">
    <inertial>
      <origin
        xyz="-0.000121891601795182 -4.91409300681922E-08 -0.00201210065266338"
        rpy="0 0 0" />
      <mass
        value="0.00115968038152584" />
      <inertia
        ixx="4.1826785795716E-08"
        ixy="-2.39268724343455E-13"
        ixz="4.0215063262228E-10"
        iyy="4.03439585123048E-08"
        iyz="3.87054839509538E-14"
        izz="1.66744809622273E-08" />
    </inertial>
    <visual>
      <origin
        xyz="0 0 0"
        rpy="0 0 0" />
      <geometry>
        <mesh
          filename="package://CLOVIS25_URDF_V1/meshes/Link64_AxisRx_IndexKnucle_Abduction.STL" />
      </geometry>
      <material
        name="">
        <color
          rgba="0.752941176470588 0.752941176470588 0.752941176470588 1" />
      </material>
    </visual>
    <collision>
      <origin
        xyz="0 0 0"
        rpy="0 0 0" />
      <geometry>
        <mesh
          filename="package://CLOVIS25_URDF_V1/meshes/Link64_AxisRx_IndexKnucle_Abduction.STL" />
      </geometry>
    </collision>
  </link>
  <joint
    name="R64_AxisRx_IndexKnucle_Abduction"
    type="revolute">
    <origin
      xyz="0 0.100710889132455 -0.0300000000000013"
      rpy="-1.5707963267949 0 1.5707963267949" />
    <parent
      link="Link46_AxisRy_Wrist_Flexion" />
    <child
      link="Link64_AxisRx_IndexKnucle_Abduction" />
    <axis
      xyz="0 0 -1" />
    <limit
      lower="0"
      upper="0"
      effort="0"
      velocity="0" />
  </joint>
  <link
    name="Link65_AxisRy_IndexKnucle_Flexion">
    <inertial>
      <origin
        xyz="0.00211406335376801 0.0145062489951183 4.40290207764926E-09"
        rpy="0 0 0" />
      <mass
        value="0.00305079596232101" />
      <inertia
        ixx="2.87529730754108E-07"
        ixy="1.55515958091808E-08"
        ixz="-1.24036018601261E-13"
        iyy="1.38377543503227E-07"
        iyz="3.76599757344904E-13"
        izz="2.29166032829321E-07" />
    </inertial>
    <visual>
      <origin
        xyz="0 0 0"
        rpy="0 0 0" />
      <geometry>
        <mesh
          filename="package://CLOVIS25_URDF_V1/meshes/Link65_AxisRy_IndexKnucle_Flexion.STL" />
      </geometry>
      <material
        name="">
        <color
          rgba="0.752941176470588 0.752941176470588 0.752941176470588 1" />
      </material>
    </visual>
    <collision>
      <origin
        xyz="0 0 0"
        rpy="0 0 0" />
      <geometry>
        <mesh
          filename="package://CLOVIS25_URDF_V1/meshes/Link65_AxisRy_IndexKnucle_Flexion.STL" />
      </geometry>
    </collision>
  </link>
  <joint
    name="R65_AxisRy_IndexKnucle_Flexion"
    type="fixed">
    <origin
      xyz="0 0 0"
      rpy="1.57079632679489 1.5707963267949 0" />
    <parent
      link="Link64_AxisRx_IndexKnucle_Abduction" />
    <child
      link="Link65_AxisRy_IndexKnucle_Flexion" />
    <axis
      xyz="0 0 0" />
  </joint>
  <link
    name="Link66_AxisRy_IndexMiddle_Flexion">
    <inertial>
      <origin
        xyz="0.00240152083460479 0.00654385041930641 -7.78004879369992E-05"
        rpy="0 0 0" />
      <mass
        value="0.00237461021631886" />
      <inertia
        ixx="1.93784109250359E-07"
        ixy="1.60821542165126E-08"
        ixz="7.95861715000478E-11"
        iyy="9.31756219047257E-08"
        iyz="3.55124367944553E-10"
        izz="1.51786468172039E-07" />
    </inertial>
    <visual>
      <origin
        xyz="0 0 0"
        rpy="0 0 0" />
      <geometry>
        <mesh
          filename="package://CLOVIS25_URDF_V1/meshes/Link66_AxisRy_IndexMiddle_Flexion.STL" />
      </geometry>
      <material
        name="">
        <color
          rgba="0.752941176470588 0.752941176470588 0.752941176470588 1" />
      </material>
    </visual>
    <collision>
      <origin
        xyz="0 0 0"
        rpy="0 0 0" />
      <geometry>
        <mesh
          filename="package://CLOVIS25_URDF_V1/meshes/Link66_AxisRy_IndexMiddle_Flexion.STL" />
      </geometry>
    </collision>
  </link>
  <joint
    name="R66_AxisRy_IndexMiddle_Flexion"
    type="revolute">
    <origin
      xyz="0 0.0300000000000014 9.99999999971579E-05"
      rpy="0 0 0" />
    <parent
      link="Link65_AxisRy_IndexKnucle_Flexion" />
    <child
      link="Link66_AxisRy_IndexMiddle_Flexion" />
    <axis
      xyz="0 0 -1" />
    <limit
      lower="0"
      upper="0"
      effort="0"
      velocity="0" />
  </joint>
  <link
    name="Link67_AxisRy_IndexTip_Flexion">
    <inertial>
      <origin
        xyz="-0.00555116931157285 0.00681823871639811 -2.21893247968202E-06"
        rpy="0 0 0" />
      <mass
        value="0.00253828371370103" />
      <inertia
        ixx="1.28437698390917E-07"
        ixy="2.58021659424467E-08"
        ixz="7.27690086499229E-12"
        iyy="8.57012975056679E-08"
        iyz="-6.31363709015457E-11"
        izz="1.10632726364164E-07" />
    </inertial>
    <visual>
      <origin
        xyz="0 0 0"
        rpy="0 0 0" />
      <geometry>
        <mesh
          filename="package://CLOVIS25_URDF_V1/meshes/Link67_AxisRy_IndexTip_Flexion.STL" />
      </geometry>
      <material
        name="">
        <color
          rgba="0.752941176470588 0.752941176470588 0.752941176470588 1" />
      </material>
    </visual>
    <collision>
      <origin
        xyz="0 0 0"
        rpy="0 0 0" />
      <geometry>
        <mesh
          filename="package://CLOVIS25_URDF_V1/meshes/Link67_AxisRy_IndexTip_Flexion.STL" />
      </geometry>
    </collision>
  </link>
  <joint
    name="R67_AxisRy_IndexTip_Flexion"
    type="revolute">
    <origin
      xyz="-0.000938526804089929 0.0189768060388912 -9.99999999971579E-05"
      rpy="0 0 0" />
    <parent
      link="Link66_AxisRy_IndexMiddle_Flexion" />
    <child
      link="Link67_AxisRy_IndexTip_Flexion" />
    <axis
      xyz="0 0 -1" />
    <limit
      lower="0"
      upper="0"
      effort="0"
      velocity="0" />
  </joint>
  <link
    name="Link68_AxisRy_MiddleFingerKnucle_Flexion">
    <inertial>
      <origin
        xyz="-0.00211406335376796 0.0145062489951181 -4.40290677528044E-09"
        rpy="0 0 0" />
      <mass
        value="0.003050795962321" />
      <inertia
        ixx="2.87529730754099E-07"
        ixy="-1.55515958091749E-08"
        ixz="-1.24036018355864E-13"
        iyy="1.38377543503217E-07"
        iyz="-3.76599757311404E-13"
        izz="2.29166032829303E-07" />
    </inertial>
    <visual>
      <origin
        xyz="0 0 0"
        rpy="0 0 0" />
      <geometry>
        <mesh
          filename="package://CLOVIS25_URDF_V1/meshes/Link68_AxisRy_MiddleFingerKnucle_Flexion.STL" />
      </geometry>
      <material
        name="">
        <color
          rgba="0.752941176470588 0.752941176470588 0.752941176470588 1" />
      </material>
    </visual>
    <collision>
      <origin
        xyz="0 0 0"
        rpy="0 0 0" />
      <geometry>
        <mesh
          filename="package://CLOVIS25_URDF_V1/meshes/Link68_AxisRy_MiddleFingerKnucle_Flexion.STL" />
      </geometry>
    </collision>
  </link>
  <joint
    name="R68_AxisRy_MiddleFingerKnucle_Flexion"
    type="revolute">
    <origin
      xyz="0 0.0958000000000002 -0.012145230173743"
      rpy="-3.14159265358979 0 -3.14159265358979" />
    <parent
      link="Link46_AxisRy_Wrist_Flexion" />
    <child
      link="Link68_AxisRy_MiddleFingerKnucle_Flexion" />
    <axis
      xyz="0 0 -1" />
    <limit
      lower="0"
      upper="0"
      effort="0"
      velocity="0" />
  </joint>
  <link
    name="Link69_AxisRy_MiddleFingerMiddle_Flexion">
    <inertial>
      <origin
        xyz="0.0024015208346044 0.00654385041930691 -7.78004879364545E-05"
        rpy="0 0 0" />
      <mass
        value="0.00237461021631886" />
      <inertia
        ixx="1.93784109250358E-07"
        ixy="1.60821542165148E-08"
        ixz="7.95861715001936E-11"
        iyy="9.31756219047187E-08"
        iyz="3.55124367944327E-10"
        izz="1.51786468172031E-07" />
    </inertial>
    <visual>
      <origin
        xyz="0 0 0"
        rpy="0 0 0" />
      <geometry>
        <mesh
          filename="package://CLOVIS25_URDF_V1/meshes/Link69_AxisRy_MiddleFingerMiddle_Flexion.STL" />
      </geometry>
      <material
        name="">
        <color
          rgba="0.752941176470588 0.752941176470588 0.752941176470588 1" />
      </material>
    </visual>
    <collision>
      <origin
        xyz="0 0 0"
        rpy="0 0 0" />
      <geometry>
        <mesh
          filename="package://CLOVIS25_URDF_V1/meshes/Link69_AxisRy_MiddleFingerMiddle_Flexion.STL" />
      </geometry>
    </collision>
  </link>
  <joint
    name="R69_AxisRy_MiddleFingerMiddle_Flexion"
    type="revolute">
    <origin
      xyz="0 0.0299999999999988 -9.99999999982022E-05"
      rpy="-3.14159265358979 0 3.14159265358979" />
    <parent
      link="Link68_AxisRy_MiddleFingerKnucle_Flexion" />
    <child
      link="Link69_AxisRy_MiddleFingerMiddle_Flexion" />
    <axis
      xyz="0 0 -1" />
    <limit
      lower="0"
      upper="0"
      effort="0"
      velocity="0" />
  </joint>
  <link
    name="Link81_AxisRy_MiddleFingerTip_Flexion">
    <inertial>
      <origin
        xyz="0.00555116931157487 -0.00681823871639956 -2.21893247968549E-06"
        rpy="0 0 0" />
      <mass
        value="0.00253828371370102" />
      <inertia
        ixx="1.28437698390917E-07"
        ixy="2.58021659424493E-08"
        ixz="-7.27690086496802E-12"
        iyy="8.5701297505671E-08"
        iyz="6.31363709016202E-11"
        izz="1.10632726364166E-07" />
    </inertial>
    <visual>
      <origin
        xyz="0 0 0"
        rpy="0 0 0" />
      <geometry>
        <mesh
          filename="package://CLOVIS25_URDF_V1/meshes/Link81_AxisRy_MiddleFingerTip_Flexion.STL" />
      </geometry>
      <material
        name="">
        <color
          rgba="0.752941176470588 0.752941176470588 0.752941176470588 1" />
      </material>
    </visual>
    <collision>
      <origin
        xyz="0 0 0"
        rpy="0 0 0" />
      <geometry>
        <mesh
          filename="package://CLOVIS25_URDF_V1/meshes/Link81_AxisRy_MiddleFingerTip_Flexion.STL" />
      </geometry>
    </collision>
  </link>
  <joint
    name="R81_AxisRy_MiddleFingerTip_Flexion"
    type="revolute">
    <origin
      xyz="-0.000938526804097034 0.0189768060388982 -9.99999999987781E-05"
      rpy="0 0 -3.14159265358979" />
    <parent
      link="Link69_AxisRy_MiddleFingerMiddle_Flexion" />
    <child
      link="Link81_AxisRy_MiddleFingerTip_Flexion" />
    <axis
      xyz="0 0 -1" />
    <limit
      lower="0"
      upper="0"
      effort="0"
      velocity="0" />
  </joint>
  <link
    name="Link82_AxisRy_PinkyKnucle_Flexion">
    <inertial>
      <origin
        xyz="-0.00211406335376788 0.0145062489951181 0.0089999955970932"
        rpy="0 0 0" />
      <mass
        value="0.00610159192464206" />
      <inertia
        ixx="5.75059461508256E-07"
        ixy="-3.11031916184132E-08"
        ixz="-2.48072038130763E-13"
        iyy="2.7675508700658E-07"
        iyz="-7.53199513086696E-13"
        izz="4.58332065658806E-07" />
    </inertial>
    <visual>
      <origin
        xyz="0 0 0"
        rpy="0 0 0" />
      <geometry>
        <mesh
          filename="package://CLOVIS25_URDF_V1/meshes/Link82_AxisRy_PinkyKnucle_Flexion.STL" />
      </geometry>
      <material
        name="">
        <color
          rgba="0.752941176470588 0.752941176470588 0.752941176470588 1" />
      </material>
    </visual>
    <collision>
      <origin
        xyz="0 0 0"
        rpy="0 0 0" />
      <geometry>
        <mesh
          filename="package://CLOVIS25_URDF_V1/meshes/Link82_AxisRy_PinkyKnucle_Flexion.STL" />
      </geometry>
    </collision>
  </link>
  <joint
    name="R82_AxisRy_PinkyKnucle_Flexion"
    type="revolute">
    <origin
      xyz="0 0.0958000000000002 0.0238547698262569"
      rpy="-3.14159265358979 0 -3.14159265358979" />
    <parent
      link="Link46_AxisRy_Wrist_Flexion" />
    <child
      link="Link82_AxisRy_PinkyKnucle_Flexion" />
    <axis
      xyz="0 0 -1" />
    <limit
      lower="0"
      upper="0"
      effort="0"
      velocity="0" />
  </joint>
  <link
    name="Link83_AxisRy_PinkyMiddle_Flexion">
    <inertial>
      <origin
        xyz="0.00240152083460407 0.00654385041930969 0.00892219951205621"
        rpy="0 0 0" />
      <mass
        value="0.00474922043263773" />
      <inertia
        ixx="3.87568218500722E-07"
        ixy="3.21643084330258E-08"
        ixz="1.59172343000947E-10"
        iyy="1.86351243809437E-07"
        iyz="7.10248735888107E-10"
        izz="3.03572936344067E-07" />
    </inertial>
    <visual>
      <origin
        xyz="0 0 0"
        rpy="0 0 0" />
      <geometry>
        <mesh
          filename="package://CLOVIS25_URDF_V1/meshes/Link83_AxisRy_PinkyMiddle_Flexion.STL" />
      </geometry>
      <material
        name="">
        <color
          rgba="0.752941176470588 0.752941176470588 0.752941176470588 1" />
      </material>
    </visual>
    <collision>
      <origin
        xyz="0 0 0"
        rpy="0 0 0" />
      <geometry>
        <mesh
          filename="package://CLOVIS25_URDF_V1/meshes/Link83_AxisRy_PinkyMiddle_Flexion.STL" />
      </geometry>
    </collision>
  </link>
  <joint
    name="R83_AxisRy_PinkyMiddle_Flexion"
    type="revolute">
    <origin
      xyz="0 0.0299999999999947 0.0178999999999945"
      rpy="-3.14159265358979 0 3.14159265358979" />
    <parent
      link="Link82_AxisRy_PinkyKnucle_Flexion" />
    <child
      link="Link83_AxisRy_PinkyMiddle_Flexion" />
    <axis
      xyz="0 0 -1" />
    <limit
      lower="0"
      upper="0"
      effort="0"
      velocity="0" />
  </joint>
  <link
    name="Link84_AxisRy_PinkyTip_Flexion">
    <inertial>
      <origin
        xyz="-0.00555116931157468 0.00681823871640203 0.00899778106751429"
        rpy="0 0 0" />
      <mass
        value="0.00507656742740203" />
      <inertia
        ixx="2.56875396781835E-07"
        ixy="5.16043318848952E-08"
        ixz="1.45538017299021E-11"
        iyy="1.71402595011341E-07"
        iyz="-1.26272741802822E-10"
        izz="2.21265452728333E-07" />
    </inertial>
    <visual>
      <origin
        xyz="0 0 0"
        rpy="0 0 0" />
      <geometry>
        <mesh
          filename="package://CLOVIS25_URDF_V1/meshes/Link84_AxisRy_PinkyTip_Flexion.STL" />
      </geometry>
      <material
        name="">
        <color
          rgba="0.752941176470588 0.752941176470588 0.752941176470588 1" />
      </material>
    </visual>
    <collision>
      <origin
        xyz="0 0 0"
        rpy="0 0 0" />
      <geometry>
        <mesh
          filename="package://CLOVIS25_URDF_V1/meshes/Link84_AxisRy_PinkyTip_Flexion.STL" />
      </geometry>
    </collision>
  </link>
  <joint
    name="R84_AxisRy_PinkyTip_Flexion"
    type="revolute">
    <origin
      xyz="-0.000938526804095008 0.0189768060388963 -9.99999999999994E-05"
      rpy="0 0 0" />
    <parent
      link="Link83_AxisRy_PinkyMiddle_Flexion" />
    <child
      link="Link84_AxisRy_PinkyTip_Flexion" />
    <axis
      xyz="0 0 -1" />
    <limit
      lower="0"
      upper="0"
      effort="0"
      velocity="0" />
  </joint>
  <link
    name="Link10_AxisRy_Hips_Flexion">
    <inertial>
      <origin
        xyz="-0.035491858736204 0.00091391832232043 0.018194719601768"
        rpy="0 0 0" />
      <mass
        value="0.154615097187712" />
      <inertia
        ixx="0.000129284073057895"
        ixy="5.95413093632001E-06"
        ixz="-4.73243723374356E-06"
        iyy="0.000183034354985313"
        iyz="5.32228933808359E-06"
        izz="7.52482691085157E-05" />
    </inertial>
    <visual>
      <origin
        xyz="0 0 0"
        rpy="0 0 0" />
      <geometry>
        <mesh
          filename="package://CLOVIS25_URDF_V1/meshes/Link10_AxisRy_Hips_Flexion.STL" />
      </geometry>
      <material
        name="">
        <color
          rgba="0.752941176470588 0.752941176470588 0.752941176470588 1" />
      </material>
    </visual>
    <collision>
      <origin
        xyz="0 0 0"
        rpy="0 0 0" />
      <geometry>
        <mesh
          filename="package://CLOVIS25_URDF_V1/meshes/Link10_AxisRy_Hips_Flexion.STL" />
      </geometry>
    </collision>
  </link>
  <joint
    name="R10_AxisRy_Hips_Flexion"
    type="revolute">
    <origin
      xyz="0.058997 0 -0.036813"
      rpy="0 -0.5236 3.1416" />
    <parent
      link="base_link_R0_HipsWaist_Yaw" />
    <child
      link="Link10_AxisRy_Hips_Flexion" />
    <axis
      xyz="-1 0 0" />
    <limit
      lower="-1.396"
      upper="1.396"
      effort="3.66"
      velocity="5.05" />
  </joint>
  <link
    name="Link11_AxisRx_Hips_Abduction">
    <inertial>
      <origin
        xyz="-0.000420686937343747 -0.0141524399660883 0.0464372807980134"
        rpy="0 0 0" />
      <mass
        value="0.168812815651825" />
      <inertia
        ixx="0.000116232359472686"
        ixy="-3.41286272029201E-06"
        ixz="-2.94169778032604E-06"
        iyy="0.000163337696614815"
        iyz="-2.55918774884189E-05"
        izz="0.000177818098522985" />
    </inertial>
    <visual>
      <origin
        xyz="0 0 0"
        rpy="0 0 0" />
      <geometry>
        <mesh
          filename="package://CLOVIS25_URDF_V1/meshes/Link11_AxisRx_Hips_Abduction.STL" />
      </geometry>
      <material
        name="">
        <color
          rgba="0.752941176470588 0.752941176470588 0.752941176470588 1" />
      </material>
    </visual>
    <collision>
      <origin
        xyz="0 0 0"
        rpy="0 0 0" />
      <geometry>
        <mesh
          filename="package://CLOVIS25_URDF_V1/meshes/Link11_AxisRx_Hips_Abduction.STL" />
      </geometry>
    </collision>
  </link>
  <joint
    name="R11_AxisRx_Hips_Abduction"
    type="revolute">
    <origin
      xyz="-0.0395 0 0"
      rpy="3.14159265358979 0 1.5707963267949" />
    <parent
      link="Link10_AxisRy_Hips_Flexion" />
    <child
      link="Link11_AxisRx_Hips_Abduction" />
    <axis
      xyz="1 0 0" />
    <limit
      lower="-0.436"
      upper="1.047"
      effort="3.66"
      velocity="5.05" />
  </joint>
  <link
    name="Link12_AxisRz_Hips_Rotation">
    <inertial>
      <origin
        xyz="0.0299865209861309 0.000915006997890017 0.0395840914056425"
        rpy="0 0 0" />
      <mass
        value="0.308889411658998" />
      <inertia
        ixx="0.000258352042230296"
        ixy="-1.2017985889604E-05"
        ixz="-2.22319994912742E-05"
        iyy="0.000446775467584485"
        iyz="2.5394534120569E-05"
        izz="0.00029936684325554" />
    </inertial>
    <visual>
      <origin
        xyz="0 0 0"
        rpy="0 0 0" />
      <geometry>
        <mesh
          filename="package://CLOVIS25_URDF_V1/meshes/Link12_AxisRz_Hips_Rotation.STL" />
      </geometry>
      <material
        name="">
        <color
          rgba="0.752941176470588 0.752941176470588 0.752941176470588 1" />
      </material>
    </visual>
    <collision>
      <origin
        xyz="0 0 0"
        rpy="0 0 0" />
      <geometry>
        <mesh
          filename="package://CLOVIS25_URDF_V1/meshes/Link12_AxisRz_Hips_Rotation.STL" />
      </geometry>
    </collision>
  </link>
  <joint
    name="R12_AxisRz_Hips_Rotation"
    type="revolute">
    <origin
      xyz="0.000499999999999946 -0.0407499999999995 0.0705810704084321"
      rpy="-0.523598775598292 0 3.14159265358979" />
    <parent
      link="Link11_AxisRx_Hips_Abduction" />
    <child
      link="Link12_AxisRz_Hips_Rotation" />
    <axis
      xyz="0 0 -1" />
    <limit
      lower="-1.222"
      upper="1.571"
      effort="3.66"
      velocity="5.05" />
  </joint>
  <link
    name="Link13_AxisRy_Knee_Flexion">
    <inertial>
      <origin
        xyz="-0.00996165884627893 -3.95525887098014E-07 -0.0737094687999739"
        rpy="0 0 0" />
      <mass
        value="0.20810093518798" />
      <inertia
        ixx="0.000251269487093237"
        ixy="8.5730127038981E-11"
        ixz="5.37344393723953E-06"
        iyy="0.000240506181571732"
        iyz="1.05076277988845E-09"
        izz="7.36271056526118E-05" />
    </inertial>
    <visual>
      <origin
        xyz="0 0 0"
        rpy="0 0 0" />
      <geometry>
        <mesh
          filename="package://CLOVIS25_URDF_V1/meshes/Link13_AxisRy_Knee_Flexion.STL" />
      </geometry>
      <material
        name="">
        <color
          rgba="0.752941176470588 0.752941176470588 0.752941176470588 1" />
      </material>
    </visual>
    <collision>
      <origin
        xyz="0 0 0"
        rpy="0 0 0" />
      <geometry>
        <mesh
          filename="package://CLOVIS25_URDF_V1/meshes/Link13_AxisRy_Knee_Flexion.STL" />
      </geometry>
    </collision>
  </link>
  <joint
    name="R13_AxisRy_Knee_Flexion"
    type="revolute">
    <origin
      xyz="0 0 0.036"
      rpy="3.14159265358979 0 -3.14159265358979" />
    <parent
      link="Link12_AxisRz_Hips_Rotation" />
    <child
      link="Link13_AxisRy_Knee_Flexion" />
    <axis
      xyz="0 -1 0" />
    <limit
      lower="0"
      upper="2.094"
      effort="3.66"
      velocity="5.05" />
  </joint>
  <link
    name="Link14_AxisRy_Ankle_Flexion">
    <inertial>
      <origin
        xyz="4.88789106049125E-05 -4.22901893046279E-07 -0.000941696331463682"
        rpy="0 0 0" />
      <mass
        value="0.0198828974134902" />
      <inertia
        ixx="5.33136120702504E-06"
        ixy="5.67526433327122E-11"
        ixz="6.76121728274836E-09"
        iyy="3.84427573974656E-06"
        iyz="4.02949645609817E-12"
        izz="8.29733415735585E-06" />
    </inertial>
    <visual>
      <origin
        xyz="0 0 0"
        rpy="0 0 0" />
      <geometry>
        <mesh
          filename="package://CLOVIS25_URDF_V1/meshes/Link14_AxisRy_Ankle_Flexion.STL" />
      </geometry>
      <material
        name="">
        <color
          rgba="0.752941176470588 0.752941176470588 0.752941176470588 1" />
      </material>
    </visual>
    <collision>
      <origin
        xyz="0 0 0"
        rpy="0 0 0" />
      <geometry>
        <mesh
          filename="package://CLOVIS25_URDF_V1/meshes/Link14_AxisRy_Ankle_Flexion.STL" />
      </geometry>
    </collision>
  </link>
  <joint
    name="R14_AxisRy_Ankle_Flexion"
    type="revolute">
    <origin
      xyz="0 0 -0.14"
      rpy="0 0 0" />
    <parent
      link="Link13_AxisRy_Knee_Flexion" />
    <child
      link="Link14_AxisRy_Ankle_Flexion" />
    <axis
      xyz="0 1 0" />
    <limit
      lower="-0.96"
      upper="0.698"
      effort="3.66"
      velocity="5.05" />
  </joint>
  <link
    name="Link15_AxisRx_Ankle_Abduction">
    <inertial>
      <origin
        xyz="-0.00749525839369283 -1.00190964635871E-07 -0.0413958069840308"
        rpy="0 0 0" />
      <mass
        value="0.162069791623735" />
      <inertia
        ixx="8.37583833186822E-05"
        ixy="9.3573163269024E-11"
        ixz="5.76979843466876E-06"
        iyy="0.000111745804529979"
        iyz="5.4764380004613E-10"
        izz="0.000127010438609888" />
    </inertial>
    <visual>
      <origin
        xyz="0 0 0"
        rpy="0 0 0" />
      <geometry>
        <mesh
          filename="package://CLOVIS25_URDF_V1/meshes/Link15_AxisRx_Ankle_Abduction.STL" />
      </geometry>
      <material
        name="">
        <color
          rgba="0.752941176470588 0.752941176470588 0.752941176470588 1" />
      </material>
    </visual>
    <collision>
      <origin
        xyz="0 0 0"
        rpy="0 0 0" />
      <geometry>
        <mesh
          filename="package://CLOVIS25_URDF_V1/meshes/Link15_AxisRx_Ankle_Abduction.STL" />
      </geometry>
    </collision>
  </link>
  <joint
    name="R15_AxisRx_Ankle_Abduction"
    type="revolute">
    <origin
      xyz="0 0 0"
      rpy="0 0 -3.14159265358979" />
    <parent
      link="Link14_AxisRy_Ankle_Flexion" />
    <child
      link="Link15_AxisRx_Ankle_Abduction" />
    <axis
      xyz="1 0 0" />
    <limit
      lower="-0.96"
      upper="0.96"
      effort="3.66"
      velocity="5.05" />
  </joint>
  <link
    name="Link16_AxisRx_Toe_Flexion">
    <inertial>
      <origin
        xyz="0.0181977115240334 0.00126288994199183 -0.00954659053967732"
        rpy="0 0 0" />
      <mass
        value="0.0664189830579757" />
      <inertia
        ixx="3.9575421565876E-05"
        ixy="-1.398387168666E-06"
        ixz="4.60537840513917E-06"
        iyy="2.87049416190121E-05"
        iyz="-1.28510150088002E-07"
        izz="5.6352915404693E-05" />
    </inertial>
    <visual>
      <origin
        xyz="0 0 0"
        rpy="0 0 0" />
      <geometry>
        <mesh
          filename="package://CLOVIS25_URDF_V1/meshes/Link16_AxisRx_Toe_Flexion.STL" />
      </geometry>
      <material
        name="">
        <color
          rgba="0.752941176470588 0.752941176470588 0.752941176470588 1" />
      </material>
    </visual>
    <collision>
      <origin
        xyz="0 0 0"
        rpy="0 0 0" />
      <geometry>
        <mesh
          filename="package://CLOVIS25_URDF_V1/meshes/Link16_AxisRx_Toe_Flexion.STL" />
      </geometry>
    </collision>
  </link>
  <joint
    name="R16_AxisRx_Toe_Flexion"
    type="revolute">
    <origin
      xyz="0.055 0 -0.0425"
      rpy="0 0 0" />
    <parent
      link="Link15_AxisRx_Ankle_Abduction" />
    <child
      link="Link16_AxisRx_Toe_Flexion" />
    <axis
      xyz="0 1 0" />
    <limit
      lower="-0.785"
      upper="0"
      effort="0.44"
      velocity="5.05" />
  </joint>
  <link
    name="Link20_AxisRy_Hips_Flexion">
    <inertial>
      <origin
        xyz="-0.0191695238748907 -0.00104952349483888 -0.0352473021715194"
        rpy="0 0 0" />
      <mass
        value="0.150034857109825" />
      <inertia
        ixx="7.41467834211886E-05"
        ixy="4.27066915988223E-06"
        ixz="4.19048433769203E-06"
        iyy="0.000175384510459711"
        iyz="-5.87188592248189E-06"
        izz="0.000122352676232008" />
    </inertial>
    <visual>
      <origin
        xyz="0 0 0"
        rpy="0 0 0" />
      <geometry>
        <mesh
          filename="package://CLOVIS25_URDF_V1/meshes/Link20_AxisRy_Hips_Flexion.STL" />
      </geometry>
      <material
        name="">
        <color
          rgba="0.752941176470588 0.752941176470588 0.752941176470588 1" />
      </material>
    </visual>
    <collision>
      <origin
        xyz="0 0 0"
        rpy="0 0 0" />
      <geometry>
        <mesh
          filename="package://CLOVIS25_URDF_V1/meshes/Link20_AxisRy_Hips_Flexion.STL" />
      </geometry>
    </collision>
  </link>
  <joint
    name="R20_AxisRy_Hips_Flexion"
    type="revolute">
    <origin
      xyz="-0.0589974226119289 0 -0.0368134665205265"
      rpy="0 1.0471975511966 0" />
    <parent
      link="base_link_R0_HipsWaist_Yaw" />
    <child
      link="Link20_AxisRy_Hips_Flexion" />
    <axis
      xyz="0 0 1" />
    <limit
      lower="-1.396"
      upper="1.396"
      effort="3.66"
      velocity="5.05" />
  </joint>
  <link
    name="Link21_AxisRx_Hips_Abduction">
    <inertial>
      <origin
        xyz="0.000421585960770151 -0.0109610923852846 -0.047292225551319"
        rpy="0 0 0" />
      <mass
        value="0.168809122055464" />
      <inertia
        ixx="0.000116232144999569"
        ixy="-4.4236362113877E-06"
        ixz="-8.40343454054991E-07"
        iyy="0.000144789714142267"
        iyz="-6.52548921967783E-06"
        izz="0.000196356223785667" />
    </inertial>
    <visual>
      <origin
        xyz="0 0 0"
        rpy="0 0 0" />
      <geometry>
        <mesh
          filename="package://CLOVIS25_URDF_V1/meshes/Link21_AxisRx_Hips_Abduction.STL" />
      </geometry>
      <material
        name="">
        <color
          rgba="0.752941176470588 0.752941176470588 0.752941176470588 1" />
      </material>
    </visual>
    <collision>
      <origin
        xyz="0 0 0"
        rpy="0 0 0" />
      <geometry>
        <mesh
          filename="package://CLOVIS25_URDF_V1/meshes/Link21_AxisRx_Hips_Abduction.STL" />
      </geometry>
    </collision>
  </link>
  <joint
    name="R21_AxisRx_Hips_Abduction"
    type="revolute">
    <origin
      xyz="0 0 -0.0395000000000001"
      rpy="-1.0471975511966 0 1.5707963267949" />
    <parent
      link="Link20_AxisRy_Hips_Flexion" />
    <child
      link="Link21_AxisRx_Hips_Abduction" />
    <axis
      xyz="-1 0 0" />
    <limit
      lower="-0.436"
      upper="1.047"
      effort="3.66"
      velocity="5.05" />
  </joint>
  <link
    name="Link22_AxisRz_Hips_Rotation">
    <inertial>
      <origin
        xyz="0.029986627747195 -0.000913351495272052 0.0395841441494067"
        rpy="0 0 0" />
      <mass
        value="0.308888997867295" />
      <inertia
        ixx="0.000258350925683758"
        ixy="1.20182401297498E-05"
        ixz="-2.22308950799236E-05"
        iyy="0.000446773838832807"
        iyz="-2.53944021702722E-05"
        izz="0.000299365015684185" />
    </inertial>
    <visual>
      <origin
        xyz="0 0 0"
        rpy="0 0 0" />
      <geometry>
        <mesh
          filename="package://CLOVIS25_URDF_V1/meshes/Link22_AxisRz_Hips_Rotation.STL" />
      </geometry>
      <material
        name="">
        <color
          rgba="0.752941176470588 0.752941176470588 0.752941176470588 1" />
      </material>
    </visual>
    <collision>
      <origin
        xyz="0 0 0"
        rpy="0 0 0" />
      <geometry>
        <mesh
          filename="package://CLOVIS25_URDF_V1/meshes/Link22_AxisRz_Hips_Rotation.STL" />
      </geometry>
    </collision>
  </link>
  <joint
    name="R22_AxisRz_Hips_Rotation"
    type="revolute">
    <origin
      xyz="-0.000500000000000035 0 -0.0815000000000001"
      rpy="3.14159265358979 0 0" />
    <parent
      link="Link21_AxisRx_Hips_Abduction" />
    <child
      link="Link22_AxisRz_Hips_Rotation" />
    <axis
      xyz="0 0 -1" />
    <limit
      lower="-1.222"
      upper="1.571"
      effort="3.66"
      velocity="5.05" />
  </joint>
  <link
    name="Link23_AxisRy_Knee_Flexion">
    <inertial>
      <origin
        xyz="0.00996165887106261 3.95160131394512E-07 -0.0737094687119398"
        rpy="0 0 0" />
      <mass
        value="0.208100936749786" />
      <inertia
        ixx="0.000251269487849732"
        ixy="8.58282834484372E-11"
        ixz="-5.37344399964986E-06"
        iyy="0.000240506181810468"
        iyz="-1.05041562446282E-09"
        izz="7.36271062058323E-05" />
    </inertial>
    <visual>
      <origin
        xyz="0 0 0"
        rpy="0 0 0" />
      <geometry>
        <mesh
          filename="package://CLOVIS25_URDF_V1/meshes/Link23_AxisRy_Knee_Flexion.STL" />
      </geometry>
      <material
        name="">
        <color
          rgba="0.752941176470588 0.752941176470588 0.752941176470588 1" />
      </material>
    </visual>
    <collision>
      <origin
        xyz="0 0 0"
        rpy="0 0 0" />
      <geometry>
        <mesh
          filename="package://CLOVIS25_URDF_V1/meshes/Link23_AxisRy_Knee_Flexion.STL" />
      </geometry>
    </collision>
  </link>
  <joint
    name="R23_AxisRy_Knee_Flexion"
    type="revolute">
    <origin
      xyz="0 0 0.0360000000000001"
      rpy="-3.14159265358979 0 0" />
    <parent
      link="Link22_AxisRz_Hips_Rotation" />
    <child
      link="Link23_AxisRy_Knee_Flexion" />
    <axis
      xyz="0 1 0" />
    <limit
      lower="0"
      upper="2.094"
      effort="3.66"
      velocity="5.05" />
  </joint>
  <link
    name="Link24_AxisRy_Ankle_Flexion">
    <inertial>
      <origin
        xyz="-4.88788155061388E-05 4.2289045533439E-07 -0.000941696318087049"
        rpy="0 0 0" />
      <mass
        value="0.0198828972990001" />
      <inertia
        ixx="5.33136120560905E-06"
        ixy="5.67486535159327E-11"
        ixz="-6.76121286353277E-09"
        iyy="3.84427570506981E-06"
        iyz="-4.03028590699996E-12"
        izz="8.29733412364015E-06" />
    </inertial>
    <visual>
      <origin
        xyz="0 0 0"
        rpy="0 0 0" />
      <geometry>
        <mesh
          filename="package://CLOVIS25_URDF_V1/meshes/Link24_AxisRy_Ankle_Flexion.STL" />
      </geometry>
      <material
        name="">
        <color
          rgba="0.752941176470588 0.752941176470588 0.752941176470588 1" />
      </material>
    </visual>
    <collision>
      <origin
        xyz="0 0 0"
        rpy="0 0 0" />
      <geometry>
        <mesh
          filename="package://CLOVIS25_URDF_V1/meshes/Link24_AxisRy_Ankle_Flexion.STL" />
      </geometry>
    </collision>
  </link>
  <joint
    name="R24_AxisRy_Ankle_Flexion"
    type="revolute">
    <origin
      xyz="0 0 -0.14"
      rpy="0 0 0" />
    <parent
      link="Link23_AxisRy_Knee_Flexion" />
    <child
      link="Link24_AxisRy_Ankle_Flexion" />
    <axis
      xyz="0 1 0" />
    <limit
      lower="-0.96"
      upper="0.689"
      effort="3.66"
      velocity="5.05" />
  </joint>
  <link
    name="Link25_AxisRx_Ankle_Abduction">
    <inertial>
      <origin
        xyz="-0.00749525839677826 -1.00189232979386E-07 -0.0413958069745799"
        rpy="0 0 0" />
      <mass
        value="0.162069791661844" />
      <inertia
        ixx="8.37583831864788E-05"
        ixy="9.358357590869E-11"
        ixz="5.76979848237025E-06"
        iyy="0.000111745804626165"
        iyz="5.47634485566615E-10"
        izz="0.000127010438487016" />
    </inertial>
    <visual>
      <origin
        xyz="0 0 0"
        rpy="0 0 0" />
      <geometry>
        <mesh
          filename="package://CLOVIS25_URDF_V1/meshes/Link25_AxisRx_Ankle_Abduction.STL" />
      </geometry>
      <material
        name="">
        <color
          rgba="0.752941176470588 0.752941176470588 0.752941176470588 1" />
      </material>
    </visual>
    <collision>
      <origin
        xyz="0 0 0"
        rpy="0 0 0" />
      <geometry>
        <mesh
          filename="package://CLOVIS25_URDF_V1/meshes/Link25_AxisRx_Ankle_Abduction.STL" />
      </geometry>
    </collision>
  </link>
  <joint
    name="R25_AxisRx_Ankle_Abduction"
    type="revolute">
    <origin
      xyz="0 0 0"
      rpy="0 0 0" />
    <parent
      link="Link24_AxisRy_Ankle_Flexion" />
    <child
      link="Link25_AxisRx_Ankle_Abduction" />
    <axis
      xyz="1 0 0" />
    <limit
      lower="-0.96"
      upper="0.96"
      effort="3.66"
      velocity="5.05" />
  </joint>
  <link
    name="Link26_AxisRx_Toe_Flexion">
    <inertial>
      <origin
        xyz="0.0181977115240336 0.00126288994199178 -0.00954659053967744"
        rpy="0 0 0" />
      <mass
        value="0.066418983057976" />
      <inertia
        ixx="3.95754215658759E-05"
        ixy="-1.39838716866599E-06"
        ixz="4.60537840513909E-06"
        iyy="2.87049416190122E-05"
        iyz="-1.28510150088011E-07"
        izz="5.63529154046931E-05" />
    </inertial>
    <visual>
      <origin
        xyz="0 0 0"
        rpy="0 0 0" />
      <geometry>
        <mesh
          filename="package://CLOVIS25_URDF_V1/meshes/Link26_AxisRx_Toe_Flexion.STL" />
      </geometry>
      <material
        name="">
        <color
          rgba="0.752941176470588 0.752941176470588 0.752941176470588 1" />
      </material>
    </visual>
    <collision>
      <origin
        xyz="0 0 0"
        rpy="0 0 0" />
      <geometry>
        <mesh
          filename="package://CLOVIS25_URDF_V1/meshes/Link26_AxisRx_Toe_Flexion.STL" />
      </geometry>
    </collision>
  </link>
  <joint
    name="R26_AxisRx_Toe_Flexion"
    type="revolute">
    <origin
      xyz="0.0550000000000001 0 -0.0425"
      rpy="0 0 0" />
    <parent
      link="Link25_AxisRx_Ankle_Abduction" />
    <child
      link="Link26_AxisRx_Toe_Flexion" />
    <axis
      xyz="0 1 0" />
    <limit
      lower="-0.785"
      upper="0.96"
      effort="0.44"
      velocity="5.05" />
  </joint>
</robot>