<?xml version="1.0" encoding="utf-8"?>
<!-- This URDF was automatically created by SolidWorks to URDF Exporter! Originally created by Stephen Brawner (brawner@gmail.com) 
     Commit Version: 1.6.0-4-g7f85cfe  Build Version: 1.6.7995.38578
     For more information, please see http://wiki.ros.org/sw_urdf_exporter -->
<robot
  name="CLOVIS25_URDF_V1">
  <link
    name="base_link_R0_HipsWaist_Yaw">
    <inertial>
      <origin
        xyz="-5.06849794952834E-07 0.00646210878121351 -0.00735619477677175"
        rpy="0 0 0" />
      <mass
        value="0.387437520077023" />
      <inertia
        ixx="0.000602004181073353"
        ixy="-3.93523758397067E-09"
        ixz="8.41311463075804E-09"
        iyy="0.000554663199183094"
        iyz="0.000144231027662805"
        izz="0.000591393422265186" />
    </inertial>
    <visual>
      <origin
        xyz="0 0 0"
        rpy="0 0 0" />
      <geometry>
        <mesh
          filename="package://CLOVIS25_URDF_V1/meshes/base_link_R0_HipsWaist_Yaw.STL" />
      </geometry>
      <material
        name="">
        <color
          rgba="0.752941176470588 0.752941176470588 0.752941176470588 1" />
      </material>
    </visual>
    <collision>
      <origin
        xyz="0 0 0"
        rpy="0 0 0" />
      <geometry>
        <mesh
          filename="package://CLOVIS25_URDF_V1/meshes/base_link_R0_HipsWaist_Yaw.STL" />
      </geometry>
    </collision>
  </link>
  <link
    name="LinkR0_AxisRz_Waist_Yaw">
    <inertial>
      <origin
        xyz="1.46812364552775E-08 0.00792255367963899 0.0328105533698633"
        rpy="0 0 0" />
      <mass
        value="0.0743770113903967" />
      <inertia
        ixx="0.000109844902331301"
        ixy="6.43572843529043E-11"
        ixz="1.80691197844496E-11"
        iyy="5.27744826789087E-05"
        iyz="8.66811215600064E-06"
        izz="6.86185978836168E-05" />
    </inertial>
    <visual>
      <origin
        xyz="0 0 0"
        rpy="0 0 0" />
      <geometry>
        <mesh
          filename="package://CLOVIS25_URDF_V1/meshes/LinkR0_AxisRz_Waist_Yaw.STL" />
      </geometry>
      <material
        name="">
        <color
          rgba="0.752941176470588 0.752941176470588 0.752941176470588 1" />
      </material>
    </visual>
    <collision>
      <origin
        xyz="0 0 0"
        rpy="0 0 0" />
      <geometry>
        <mesh
          filename="package://CLOVIS25_URDF_V1/meshes/LinkR0_AxisRz_Waist_Yaw.STL" />
      </geometry>
    </collision>
  </link>
  <joint
    name="R0_AxisRz_Waist_Yaw"
    type="revolute">
    <origin
      xyz="0 0 0"
      rpy="0 0 0" />
    <parent
      link="base_link_R0_HipsWaist_Yaw" />
    <child
      link="LinkR0_AxisRz_Waist_Yaw" />
    <axis
      xyz="0 0 1" />
    <limit
      lower="-0.611"
      upper="0.611"
      effort="3.66"
      velocity="5.05" />
  </joint>
  <link
    name="Link1_AxisRx_Abs_Roll">
    <inertial>
      <origin
        xyz="-0.000419037666758406 -8.67044488957422E-06 0.00334728947605584"
        rpy="0 0 0" />
      <mass
        value="0.0285702910432507" />
      <inertia
        ixx="7.08725803682833E-06"
        ixy="-2.45830099309331E-09"
        ixz="-4.77409616773024E-08"
        iyy="2.32521875946385E-05"
        iyz="-1.59332092976527E-09"
        izz="2.62164733137173E-05" />
    </inertial>
    <visual>
      <origin
        xyz="0 0 0"
        rpy="0 0 0" />
      <geometry>
        <mesh
          filename="package://CLOVIS25_URDF_V1/meshes/Link1_AxisRx_Abs_Roll.STL" />
      </geometry>
      <material
        name="">
        <color
          rgba="0.698039215686274 0.698039215686274 0.698039215686274 1" />
      </material>
    </visual>
    <collision>
      <origin
        xyz="0 0 0"
        rpy="0 0 0" />
      <geometry>
        <mesh
          filename="package://CLOVIS25_URDF_V1/meshes/Link1_AxisRx_Abs_Roll.STL" />
      </geometry>
    </collision>
  </link>
  <joint
    name="R1_AxisRx_Abs_Roll"
    type="revolute">
    <origin
      xyz="0 0 0.0830000000000002"
      rpy="0 0 1.5707963267949" />
    <parent
      link="LinkR0_AxisRz_Waist_Yaw" />
    <child
      link="Link1_AxisRx_Abs_Roll" />
    <axis
      xyz="-1 0 0" />
    <limit
      lower="-0.524"
      upper="0.524"
      effort="3.66"
      velocity="5.05" />
  </joint>
  <link
    name="Link2_AxisRy_Abs_Pitch">
    <inertial>
      <origin
        xyz="0.0116501815545738 0.000444755823082563 0.0990057387692196"
        rpy="0 0 0" />
      <mass
        value="1.76578960853427" />
      <inertia
        ixx="0.00272833770966601"
        ixy="-2.20261467407082E-07"
        ixz="8.18791957211433E-05"
        iyy="0.00286417267442453"
        iyz="4.10693898067705E-07"
        izz="0.00262213378106293" />
    </inertial>
    <visual>
      <origin
        xyz="0 0 0"
        rpy="0 0 0" />
      <geometry>
        <mesh
          filename="package://CLOVIS25_URDF_V1/meshes/Link2_AxisRy_Abs_Pitch.STL" />
      </geometry>
      <material
        name="">
        <color
          rgba="0.752941176470588 0.752941176470588 0.752941176470588 1" />
      </material>
    </visual>
    <collision>
      <origin
        xyz="0 0 0"
        rpy="0 0 0" />
      <geometry>
        <mesh
          filename="package://CLOVIS25_URDF_V1/meshes/Link2_AxisRy_Abs_Pitch.STL" />
      </geometry>
    </collision>
  </link>
  <joint
    name="R2_AxisRy_Abs_Pitch"
    type="revolute">
    <origin
      xyz="0 0 0"
      rpy="0 0 0" />
    <parent
      link="Link1_AxisRx_Abs_Roll" />
    <child
      link="Link2_AxisRy_Abs_Pitch" />
    <axis
      xyz="0 -1 0" />
    <limit
      lower="-0.689"
      upper="0.785"
      effort="3.66"
      velocity="5.05" />
  </joint>
  <link
    name="Link30_AxisRy_Shoulder_Flexion">
    <inertial>
      <origin
        xyz="-0.00121122065822729 -0.00325038076073664 0.0120544903508713"
        rpy="0 0 0" />
      <mass
        value="0.0372580130703828" />
      <inertia
        ixx="1.59289941290388E-05"
        ixy="-1.20792452999149E-06"
        ixz="-4.79405065236243E-07"
        iyy="1.63933970089758E-05"
        iyz="-8.02786738789982E-07"
        izz="2.03149647590168E-05" />
    </inertial>
    <visual>
      <origin
        xyz="0 0 0"
        rpy="0 0 0" />
      <geometry>
        <mesh
          filename="package://CLOVIS25_URDF_V1/meshes/Link30_AxisRy_Shoulder_Flexion.STL" />
      </geometry>
      <material
        name="">
        <color
          rgba="0.752941176470588 0.752941176470588 0.752941176470588 1" />
      </material>
    </visual>
    <collision>
      <origin
        xyz="0 0 0"
        rpy="0 0 0" />
      <geometry>
        <mesh
          filename="package://CLOVIS25_URDF_V1/meshes/Link30_AxisRy_Shoulder_Flexion.STL" />
      </geometry>
    </collision>
  </link>
  <joint
    name="R30_AxisRy_Shoulder_Flexion"
    type="revolute">
    <origin
      xyz="0.0289259399205682 -0.101367916470833 0.130853241275273"
      rpy="-0.252680255142087 1.30019891167267 -1.5707963267949" />
    <parent
      link="Link2_AxisRy_Abs_Pitch" />
    <child
      link="Link30_AxisRy_Shoulder_Flexion" />
    <axis
      xyz="0 0 1" />
    <limit
      lower="0"
      upper="0"
      effort="0"
      velocity="0" />
  </joint>
  <link
    name="Link31_AxisRz_Shoulder_Rotation">
    <inertial>
      <origin
        xyz="0.0310376632963733 0.0149615998455135 -0.00284843103933211"
        rpy="0 0 0" />
      <mass
        value="0.0306387760752887" />
      <inertia
        ixx="1.91180450287481E-05"
        ixy="-2.81655737035407E-07"
        ixz="8.43328137709066E-07"
        iyy="2.64927352089561E-05"
        iyz="-1.49756484162896E-07"
        izz="1.4496990488765E-05" />
    </inertial>
    <visual>
      <origin
        xyz="0 0 0"
        rpy="0 0 0" />
      <geometry>
        <mesh
          filename="package://CLOVIS25_URDF_V1/meshes/Link31_AxisRz_Shoulder_Rotation.STL" />
      </geometry>
      <material
        name="">
        <color
          rgba="0.752941176470588 0.752941176470588 0.752941176470588 1" />
      </material>
    </visual>
    <collision>
      <origin
        xyz="0 0 0"
        rpy="0 0 0" />
      <geometry>
        <mesh
          filename="package://CLOVIS25_URDF_V1/meshes/Link31_AxisRz_Shoulder_Rotation.STL" />
      </geometry>
    </collision>
  </link>
  <joint
    name="R31_AxisRz_Shoulder_Rotation"
    type="revolute">
    <origin
      xyz="0 0 0.0185"
      rpy="1.57079632679489 -1.31811607165281 -1.57079632679489" />
    <parent
      link="Link30_AxisRy_Shoulder_Flexion" />
    <child
      link="Link31_AxisRz_Shoulder_Rotation" />
    <axis
      xyz="0 0 -1" />
    <limit
      lower="0"
      upper="0"
      effort="0"
      velocity="0" />
  </joint>
  <link
    name="Link32_AxisRx_Shoulder_Abduction">
    <inertial>
      <origin
        xyz="0.0104532597532833 0.0621634371379234 -0.0367102436813666"
        rpy="0 0 0" />
      <mass
        value="0.102687647799617" />
      <inertia
        ixx="0.000190390945386139"
        ixy="-3.56957902606995E-06"
        ixz="8.37982643908598E-06"
        iyy="8.9509217631079E-05"
        iyz="1.36359033582064E-05"
        izz="0.000128468014055637" />
    </inertial>
    <visual>
      <origin
        xyz="0 0 0"
        rpy="0 0 0" />
      <geometry>
        <mesh
          filename="package://CLOVIS25_URDF_V1/meshes/Link32_AxisRx_Shoulder_Abduction.STL" />
      </geometry>
      <material
        name="">
        <color
          rgba="0.752941176470588 0.752941176470588 0.752941176470588 1" />
      </material>
    </visual>
    <collision>
      <origin
        xyz="0 0 0"
        rpy="0 0 0" />
      <geometry>
        <mesh
          filename="package://CLOVIS25_URDF_V1/meshes/Link32_AxisRx_Shoulder_Abduction.STL" />
      </geometry>
    </collision>
  </link>
  <joint
    name="R32_AxisRx_Shoulder_Abduction"
    type="revolute">
    <origin
      xyz="0.0399999999999999 0.0350000000000001 -2.70284418109334E-05"
      rpy="-1.5707963267949 0.270597415122226 0" />
    <parent
      link="Link31_AxisRz_Shoulder_Rotation" />
    <child
      link="Link32_AxisRx_Shoulder_Abduction" />
    <axis
      xyz="0 0 -1" />
    <limit
      lower="0"
      upper="0"
      effort="0"
      velocity="0" />
  </joint>
  <link
    name="Link33_AxisRy_Elbow_Flexion">
    <inertial>
      <origin
        xyz="-0.00807277244123872 -0.0218914344069931 2.79389832852361E-07"
        rpy="0 0 0" />
      <mass
        value="0.0625251373156171" />
      <inertia
        ixx="2.66478352150102E-05"
        ixy="6.31835903644818E-07"
        ixz="-3.71122215387657E-11"
        iyy="2.90857173843087E-05"
        iyz="-2.29744106493057E-10"
        izz="2.16871210520696E-05" />
    </inertial>
    <visual>
      <origin
        xyz="0 0 0"
        rpy="0 0 0" />
      <geometry>
        <mesh
          filename="package://CLOVIS25_URDF_V1/meshes/Link33_AxisRy_Elbow_Flexion.STL" />
      </geometry>
      <material
        name="">
        <color
          rgba="0.752941176470588 0.752941176470588 0.752941176470588 1" />
      </material>
    </visual>
    <collision>
      <origin
        xyz="0 0 0"
        rpy="0 0 0" />
      <geometry>
        <mesh
          filename="package://CLOVIS25_URDF_V1/meshes/Link33_AxisRy_Elbow_Flexion.STL" />
      </geometry>
    </collision>
  </link>
  <joint
    name="R33_AxisRy_Elbow_Flexion"
    type="revolute">
    <origin
      xyz="0.0113302428061854 0.129505311080098 -0.035"
      rpy="1.5707963267949 0 -1.65806278939461" />
    <parent
      link="Link32_AxisRx_Shoulder_Abduction" />
    <child
      link="Link33_AxisRy_Elbow_Flexion" />
    <axis
      xyz="0 0 -1" />
    <limit
      lower="0"
      upper="0"
      effort="0"
      velocity="0" />
  </joint>
  <link
    name="Link34_AxisRz_Wrist_Rotation">
    <inertial>
      <origin
        xyz="0.000526763744020914 0.000899599310191117 -0.0255225516370474"
        rpy="0 0 0" />
      <mass
        value="0.095705310536798" />
      <inertia
        ixx="5.31202839633431E-05"
        ixy="-5.32218440986154E-08"
        ixz="1.77417951512438E-07"
        iyy="5.30307409761996E-05"
        iyz="1.14726761693417E-06"
        izz="3.7961650590323E-05" />
    </inertial>
    <visual>
      <origin
        xyz="0 0 0"
        rpy="0 0 0" />
      <geometry>
        <mesh
          filename="package://CLOVIS25_URDF_V1/meshes/Link34_AxisRz_Wrist_Rotation.STL" />
      </geometry>
      <material
        name="">
        <color
          rgba="0.752941176470588 0.752941176470588 0.752941176470588 1" />
      </material>
    </visual>
    <collision>
      <origin
        xyz="0 0 0"
        rpy="0 0 0" />
      <geometry>
        <mesh
          filename="package://CLOVIS25_URDF_V1/meshes/Link34_AxisRz_Wrist_Rotation.STL" />
      </geometry>
    </collision>
  </link>
  <joint
    name="R34_AxisRz_Wrist_Rotation"
    type="revolute">
    <origin
      xyz="-0.0399999999999999 -0.019 0"
      rpy="0 1.5707963267949 0" />
    <parent
      link="Link33_AxisRy_Elbow_Flexion" />
    <child
      link="Link34_AxisRz_Wrist_Rotation" />
    <axis
      xyz="0 0 -1" />
    <limit
      lower="0"
      upper="0"
      effort="0"
      velocity="0" />
  </joint>
  <link
    name="Link35_AxisRx_Wrist_Abduction">
    <inertial>
      <origin
        xyz="0.00813435863366127 -4.05206365936689E-07 5.4614712585721E-08"
        rpy="0 0 0" />
      <mass
        value="0.0129110778126474" />
      <inertia
        ixx="5.34580369587511E-06"
        ixy="-1.03772626655353E-10"
        ixz="6.34307336220285E-11"
        iyy="1.41876387165846E-06"
        iyz="-1.77315332039345E-11"
        izz="5.32098561653814E-06" />
    </inertial>
    <visual>
      <origin
        xyz="0 0 0"
        rpy="0 0 0" />
      <geometry>
        <mesh
          filename="package://CLOVIS25_URDF_V1/meshes/Link35_AxisRx_Wrist_Abduction.STL" />
      </geometry>
      <material
        name="">
        <color
          rgba="0.752941176470588 0.752941176470588 0.752941176470588 1" />
      </material>
    </visual>
    <collision>
      <origin
        xyz="0 0 0"
        rpy="0 0 0" />
      <geometry>
        <mesh
          filename="package://CLOVIS25_URDF_V1/meshes/Link35_AxisRx_Wrist_Abduction.STL" />
      </geometry>
    </collision>
  </link>
  <joint
    name="R35_AxisRx_Wrist_Abduction"
    type="revolute">
    <origin
      xyz="0 0 -0.0931377805455123"
      rpy="3.14159265358979 -1.5707963267949 0" />
    <parent
      link="Link34_AxisRz_Wrist_Rotation" />
    <child
      link="Link35_AxisRx_Wrist_Abduction" />
    <axis
      xyz="0 0 -1" />
    <limit
      lower="0"
      upper="0"
      effort="0"
      velocity="0" />
  </joint>
  <link
    name="Link36_AxisRy_Wrist_Flexion">
    <inertial>
      <origin
        xyz="-0.00278270226149452 0.0506978853954537 -0.000512408108842817"
        rpy="0 0 0" />
      <mass
        value="0.094866835573617" />
      <inertia
        ixx="6.39849613428145E-05"
        ixy="5.73647920852711E-06"
        ixz="3.49414578855144E-06"
        iyy="2.95679718318229E-05"
        iyz="-7.83640400248719E-06"
        izz="4.67669259635976E-05" />
    </inertial>
    <visual>
      <origin
        xyz="0 0 0"
        rpy="0 0 0" />
      <geometry>
        <mesh
          filename="package://CLOVIS25_URDF_V1/meshes/Link36_AxisRy_Wrist_Flexion.STL" />
      </geometry>
      <material
        name="">
        <color
          rgba="0.752941176470588 0.752941176470588 0.752941176470588 1" />
      </material>
    </visual>
    <collision>
      <origin
        xyz="0 0 0"
        rpy="0 0 0" />
      <geometry>
        <mesh
          filename="package://CLOVIS25_URDF_V1/meshes/Link36_AxisRy_Wrist_Flexion.STL" />
      </geometry>
    </collision>
  </link>
  <joint
    name="R36_AxisRy_Wrist_Flexion"
    type="revolute">
    <origin
      xyz="0 0 0"
      rpy="1.5707963267949 -1.48352986419518 0" />
    <parent
      link="Link35_AxisRx_Wrist_Abduction" />
    <child
      link="Link36_AxisRy_Wrist_Flexion" />
    <axis
      xyz="0 0 -1" />
    <limit
      lower="0"
      upper="0"
      effort="0"
      velocity="0" />
  </joint>
  <link
    name="Link51_AxisRz_ThumbKnucle_Rotation">
    <inertial>
      <origin
        xyz="-4.91409359593131E-08 -0.000121891601792309 0.00201210065266348"
        rpy="0 0 0" />
      <mass
        value="0.00115968038152584" />
      <inertia
        ixx="4.03439585122941E-08"
        ixy="-2.3926872433953E-13"
        ixz="-3.87054839911192E-14"
        iyy="4.18267857957112E-08"
        iyz="-4.02150632626533E-10"
        izz="1.66744809622268E-08" />
    </inertial>
    <visual>
      <origin
        xyz="0 0 0"
        rpy="0 0 0" />
      <geometry>
        <mesh
          filename="package://CLOVIS25_URDF_V1/meshes/Link51_AxisRz_ThumbKnucle_Rotation.STL" />
      </geometry>
      <material
        name="">
        <color
          rgba="0.752941176470588 0.752941176470588 0.752941176470588 1" />
      </material>
    </visual>
    <collision>
      <origin
        xyz="0 0 0"
        rpy="0 0 0" />
      <geometry>
        <mesh
          filename="package://CLOVIS25_URDF_V1/meshes/Link51_AxisRz_ThumbKnucle_Rotation.STL" />
      </geometry>
    </collision>
  </link>
  <joint
    name="R51_AxisRz_ThumbKnucle_Rotation"
    type="revolute">
    <origin
      xyz="0.0208992160414317 0.0382 -0.0217863192850372"
      rpy="-1.5707963267949 0 3.14159265358979" />
    <parent
      link="Link36_AxisRy_Wrist_Flexion" />
    <child
      link="Link51_AxisRz_ThumbKnucle_Rotation" />
    <axis
      xyz="0 0 -1" />
    <limit
      lower="0"
      upper="0"
      effort="0"
      velocity="0" />
  </joint>
  <link
    name="Link52_AxisRy_ThumbKnucle_Flexion">
    <inertial>
      <origin
        xyz="0.00616866200396443 -0.0146131442688366 -8.87240668989708E-08"
        rpy="0 0 0" />
      <mass
        value="0.00310333576369737" />
      <inertia
        ixx="2.79345952527195E-07"
        ixy="5.45699827270546E-08"
        ixz="1.93583934036912E-12"
        iyy="1.60619700743313E-07"
        iyz="-1.82698794772639E-12"
        izz="2.38435467591377E-07" />
    </inertial>
    <visual>
      <origin
        xyz="0 0 0"
        rpy="0 0 0" />
      <geometry>
        <mesh
          filename="package://CLOVIS25_URDF_V1/meshes/Link52_AxisRy_ThumbKnucle_Flexion.STL" />
      </geometry>
      <material
        name="">
        <color
          rgba="0.752941176470588 0.752941176470588 0.752941176470588 1" />
      </material>
    </visual>
    <collision>
      <origin
        xyz="0 0 0"
        rpy="0 0 0" />
      <geometry>
        <mesh
          filename="package://CLOVIS25_URDF_V1/meshes/Link52_AxisRy_ThumbKnucle_Flexion.STL" />
      </geometry>
    </collision>
  </link>
  <joint
    name="R52_AxisRy_ThumbKnucle_Flexion"
    type="revolute">
    <origin
      xyz="0 0.0289711683278987 -0.00778918517667555"
      rpy="3.14159265358979 -1.5707963267949 0" />
    <parent
      link="Link51_AxisRz_ThumbKnucle_Rotation" />
    <child
      link="Link52_AxisRy_ThumbKnucle_Flexion" />
    <axis
      xyz="0 0 1" />
    <limit
      lower="0"
      upper="0"
      effort="0"
      velocity="0" />
  </joint>
  <link
    name="Link53_AxisRy_Thumb_Flexion">
    <inertial>
      <origin
        xyz="7.16902495649374E-05 0.00984633190079666 -0.000109122506526033"
        rpy="0 0 0" />
      <mass
        value="0.0038950256358541" />
      <inertia
        ixx="3.31740758410824E-07"
        ixy="8.52234616085922E-08"
        ixz="-3.03665120916451E-10"
        iyy="1.4896051880238E-07"
        iyz="8.3187693987598E-10"
        izz="3.11286681941713E-07" />
    </inertial>
    <visual>
      <origin
        xyz="0 0 0"
        rpy="0 0 0" />
      <geometry>
        <mesh
          filename="package://CLOVIS25_URDF_V1/meshes/Link53_AxisRy_Thumb_Flexion.STL" />
      </geometry>
      <material
        name="">
        <color
          rgba="0.752941176470588 0.752941176470588 0.752941176470588 1" />
      </material>
    </visual>
    <collision>
      <origin
        xyz="0 0 0"
        rpy="0 0 0" />
      <geometry>
        <mesh
          filename="package://CLOVIS25_URDF_V1/meshes/Link53_AxisRy_Thumb_Flexion.STL" />
      </geometry>
    </collision>
  </link>
  <joint
    name="R53_AxisRy_Thumb_Flexion"
    type="revolute">
    <origin
      xyz="0 0 0"
      rpy="0 0 0" />
    <parent
      link="Link52_AxisRy_ThumbKnucle_Flexion" />
    <child
      link="Link53_AxisRy_Thumb_Flexion" />
    <axis
      xyz="0 0 -1" />
    <limit
      lower="0"
      upper="0"
      effort="0"
      velocity="0" />
  </joint>
  <link
    name="Link54_AxisRx_IndexKnucle_Abduction">
    <inertial>
      <origin
        xyz="0.000121891601791602 4.91409239897211E-08 -0.00201210065265256"
        rpy="0 0 0" />
      <mass
        value="0.00115968038152584" />
      <inertia
        ixx="4.18267857957198E-08"
        ixy="-2.39268722724592E-13"
        ixz="-4.02150632623775E-10"
        iyy="4.03439585123012E-08"
        iyz="-3.87054859980587E-14"
        izz="1.66744809622338E-08" />
    </inertial>
    <visual>
      <origin
        xyz="0 0 0"
        rpy="0 0 0" />
      <geometry>
        <mesh
          filename="package://CLOVIS25_URDF_V1/meshes/Link54_AxisRx_IndexKnucle_Abduction.STL" />
      </geometry>
      <material
        name="">
        <color
          rgba="0.752941176470588 0.752941176470588 0.752941176470588 1" />
      </material>
    </visual>
    <collision>
      <origin
        xyz="0 0 0"
        rpy="0 0 0" />
      <geometry>
        <mesh
          filename="package://CLOVIS25_URDF_V1/meshes/Link54_AxisRx_IndexKnucle_Abduction.STL" />
      </geometry>
    </collision>
  </link>
  <joint
    name="R54_AxisRx_IndexKnucle_Abduction"
    type="revolute">
    <origin
      xyz="0 0.100710889132455 -0.0300000000000001"
      rpy="-1.5707963267949 0 -1.5707963267949" />
    <parent
      link="Link36_AxisRy_Wrist_Flexion" />
    <child
      link="Link54_AxisRx_IndexKnucle_Abduction" />
    <axis
      xyz="0 0 -1" />
    <limit
      lower="0"
      upper="0"
      effort="0"
      velocity="0" />
  </joint>
  <link
    name="Link55_AxisRy_IndexKnucle_Flexion">
    <inertial>
      <origin
        xyz="-0.00211406335375972 0.0145062489951216 -4.40290241071617E-09"
        rpy="0 0 0" />
      <mass
        value="0.00305079596232099" />
      <inertia
        ixx="2.87529730754127E-07"
        ixy="-1.55515958091936E-08"
        ixz="-1.24036019437898E-13"
        iyy="1.38377543503246E-07"
        iyz="-3.76599756772825E-13"
        izz="2.29166032829361E-07" />
    </inertial>
    <visual>
      <origin
        xyz="0 0 0"
        rpy="0 0 0" />
      <geometry>
        <mesh
          filename="package://CLOVIS25_URDF_V1/meshes/Link55_AxisRy_IndexKnucle_Flexion.STL" />
      </geometry>
      <material
        name="">
        <color
          rgba="0.752941176470588 0.752941176470588 0.752941176470588 1" />
      </material>
    </visual>
    <collision>
      <origin
        xyz="0 0 0"
        rpy="0 0 0" />
      <geometry>
        <mesh
          filename="package://CLOVIS25_URDF_V1/meshes/Link55_AxisRy_IndexKnucle_Flexion.STL" />
      </geometry>
    </collision>
  </link>
  <joint
    name="R55_AxisRy_IndexKnucle_Flexion"
    type="revolute">
    <origin
      xyz="0 0 0"
      rpy="1.5707963267949 -1.5707963267949 0" />
    <parent
      link="Link54_AxisRx_IndexKnucle_Abduction" />
    <child
      link="Link55_AxisRy_IndexKnucle_Flexion" />
    <axis
      xyz="0 0 -1" />
    <limit
      lower="0"
      upper="0"
      effort="0"
      velocity="0" />
  </joint>
  <link
    name="Link56_AxisRy_IndexMiddle_Flexion">
    <inertial>
      <origin
        xyz="0.00240152083457901 0.00654385041932923 -7.78004879410724E-05"
        rpy="0 0 0" />
      <mass
        value="0.00237461021631888" />
      <inertia
        ixx="1.93784109250359E-07"
        ixy="1.60821542165139E-08"
        ixz="7.95861715001972E-11"
        iyy="9.31756219047182E-08"
        iyz="3.5512436794446E-10"
        izz="1.51786468172031E-07" />
    </inertial>
    <visual>
      <origin
        xyz="0 0 0"
        rpy="0 0 0" />
      <geometry>
        <mesh
          filename="package://CLOVIS25_URDF_V1/meshes/Link56_AxisRy_IndexMiddle_Flexion.STL" />
      </geometry>
      <material
        name="">
        <color
          rgba="0.752941176470588 0.752941176470588 0.752941176470588 1" />
      </material>
    </visual>
    <collision>
      <origin
        xyz="0 0 0"
        rpy="0 0 0" />
      <geometry>
        <mesh
          filename="package://CLOVIS25_URDF_V1/meshes/Link56_AxisRy_IndexMiddle_Flexion.STL" />
      </geometry>
    </collision>
  </link>
  <joint
    name="R56_AxisRy_IndexMiddle_Flexion"
    type="revolute">
    <origin
      xyz="0 0.0300000000000013 0"
      rpy="-3.14159265358979 0 3.14159265358979" />
    <parent
      link="Link55_AxisRy_IndexKnucle_Flexion" />
    <child
      link="Link56_AxisRy_IndexMiddle_Flexion" />
    <axis
      xyz="0 0 -1" />
    <limit
      lower="0"
      upper="0"
      effort="0"
      velocity="0" />
  </joint>
  <link
    name="Link57_AxisRy_IndexTip_Flexion">
    <inertial>
      <origin
        xyz="-0.00555116931160246 0.00681823871642395 -2.21893248580907E-06"
        rpy="0 0 0" />
      <mass
        value="0.00253828371370101" />
      <inertia
        ixx="1.28437698390913E-07"
        ixy="2.5802165942452E-08"
        ixz="7.2769008648784E-12"
        iyy="8.57012975056659E-08"
        iyz="-6.31363709014415E-11"
        izz="1.10632726364158E-07" />
    </inertial>
    <visual>
      <origin
        xyz="0 0 0"
        rpy="0 0 0" />
      <geometry>
        <mesh
          filename="package://CLOVIS25_URDF_V1/meshes/Link57_AxisRy_IndexTip_Flexion.STL" />
      </geometry>
      <material
        name="">
        <color
          rgba="0.752941176470588 0.752941176470588 0.752941176470588 1" />
      </material>
    </visual>
    <collision>
      <origin
        xyz="0 0 0"
        rpy="0 0 0" />
      <geometry>
        <mesh
          filename="package://CLOVIS25_URDF_V1/meshes/Link57_AxisRy_IndexTip_Flexion.STL" />
      </geometry>
    </collision>
  </link>
  <joint
    name="R57_AxisRy_IndexTip_Flexion"
    type="revolute">
    <origin
      xyz="-0.000938526804101725 0.0189768060389028 -0.000100000000000017"
      rpy="0 0 0" />
    <parent
      link="Link56_AxisRy_IndexMiddle_Flexion" />
    <child
      link="Link57_AxisRy_IndexTip_Flexion" />
    <axis
      xyz="0 0 -1" />
    <limit
      lower="0"
      upper="0"
      effort="0"
      velocity="0" />
  </joint>
  <link
    name="Link58_AxisRy_MiddleFingerKnucle_Flexion">
    <inertial>
      <origin
        xyz="-0.00211406335375619 0.0145062489951234 -4.40290519668207E-09"
        rpy="0 0 0" />
      <mass
        value="0.00305079596232101" />
      <inertia
        ixx="2.87529730754123E-07"
        ixy="-1.55515958092051E-08"
        ixz="-1.24036019309277E-13"
        iyy="1.38377543503299E-07"
        iyz="-3.76599757386471E-13"
        izz="2.29166032829408E-07" />
    </inertial>
    <visual>
      <origin
        xyz="0 0 0"
        rpy="0 0 0" />
      <geometry>
        <mesh
          filename="package://CLOVIS25_URDF_V1/meshes/Link58_AxisRy_MiddleFingerKnucle_Flexion.STL" />
      </geometry>
      <material
        name="">
        <color
          rgba="0.752941176470588 0.752941176470588 0.752941176470588 1" />
      </material>
    </visual>
    <collision>
      <origin
        xyz="0 0 0"
        rpy="0 0 0" />
      <geometry>
        <mesh
          filename="package://CLOVIS25_URDF_V1/meshes/Link58_AxisRy_MiddleFingerKnucle_Flexion.STL" />
      </geometry>
    </collision>
  </link>
  <joint
    name="R58_AxisRy_MiddleFingerKnucle_Flexion"
    type="revolute">
    <origin
      xyz="0 0.0957999999999998 -0.0121"
      rpy="0 0 0" />
    <parent
      link="Link36_AxisRy_Wrist_Flexion" />
    <child
      link="Link58_AxisRy_MiddleFingerKnucle_Flexion" />
    <axis
      xyz="0 0 -1" />
    <limit
      lower="0"
      upper="0"
      effort="0"
      velocity="0" />
  </joint>
  <link
    name="Link59_AxisRy_MiddleFingerMiddle_Flexion">
    <inertial>
      <origin
        xyz="0.00240152083459541 0.00654385041930861 -7.78004879377382E-05"
        rpy="0 0 0" />
      <mass
        value="0.00237461021631887" />
      <inertia
        ixx="1.93784109250358E-07"
        ixy="1.60821542165148E-08"
        ixz="7.95861715003283E-11"
        iyy="9.31756219047172E-08"
        iyz="3.5512436794424E-10"
        izz="1.51786468172029E-07" />
    </inertial>
    <visual>
      <origin
        xyz="0 0 0"
        rpy="0 0 0" />
      <geometry>
        <mesh
          filename="package://CLOVIS25_URDF_V1/meshes/Link59_AxisRy_MiddleFingerMiddle_Flexion.STL" />
      </geometry>
      <material
        name="">
        <color
          rgba="0.752941176470588 0.752941176470588 0.752941176470588 1" />
      </material>
    </visual>
    <collision>
      <origin
        xyz="0 0 0"
        rpy="0 0 0" />
      <geometry>
        <mesh
          filename="package://CLOVIS25_URDF_V1/meshes/Link59_AxisRy_MiddleFingerMiddle_Flexion.STL" />
      </geometry>
    </collision>
  </link>
  <joint
    name="R59_AxisRy_MiddleFingerMiddle_Flexion"
    type="revolute">
    <origin
      xyz="0 0.0300000000000018 -0.000100000000004839"
      rpy="-3.14159265358979 0 -3.14159265358979" />
    <parent
      link="Link58_AxisRy_MiddleFingerKnucle_Flexion" />
    <child
      link="Link59_AxisRy_MiddleFingerMiddle_Flexion" />
    <axis
      xyz="0 0 -1" />
    <limit
      lower="0"
      upper="0"
      effort="0"
      velocity="0" />
  </joint>
  <link
    name="Link71_AxisRy_MiddleFingerTip_Flexion">
    <inertial>
      <origin
        xyz="-0.00555116931157984 0.00681823871639733 -2.21893248081653E-06"
        rpy="0 0 0" />
      <mass
        value="0.00253828371370102" />
      <inertia
        ixx="1.28437698390917E-07"
        ixy="2.58021659424504E-08"
        ixz="7.27690086485789E-12"
        iyy="8.57012975056682E-08"
        iyz="-6.31363709015151E-11"
        izz="1.10632726364164E-07" />
    </inertial>
    <visual>
      <origin
        xyz="0 0 0"
        rpy="0 0 0" />
      <geometry>
        <mesh
          filename="package://CLOVIS25_URDF_V1/meshes/Link71_AxisRy_MiddleFingerTip_Flexion.STL" />
      </geometry>
      <material
        name="">
        <color
          rgba="0.752941176470588 0.752941176470588 0.752941176470588 1" />
      </material>
    </visual>
    <collision>
      <origin
        xyz="0 0 0"
        rpy="0 0 0" />
      <geometry>
        <mesh
          filename="package://CLOVIS25_URDF_V1/meshes/Link71_AxisRy_MiddleFingerTip_Flexion.STL" />
      </geometry>
    </collision>
  </link>
  <joint
    name="R71_AxisRy_MiddleFingerTip_Flexion"
    type="revolute">
    <origin
      xyz="-0.000938526804097312 0.0189768060388983 -0.000100000000004839"
      rpy="0 0 0" />
    <parent
      link="Link59_AxisRy_MiddleFingerMiddle_Flexion" />
    <child
      link="Link71_AxisRy_MiddleFingerTip_Flexion" />
    <axis
      xyz="0 0 -1" />
    <limit
      lower="0"
      upper="0"
      effort="0"
      velocity="0" />
  </joint>
  <link
    name="Link72_AxisRy_PinkyKnucle_Flexion">
    <inertial>
      <origin
        xyz="-0.00211406335375958 0.0145062489951216 -0.00900000440290133"
        rpy="0 0 0" />
      <mass
        value="0.00610159192464204" />
      <inertia
        ixx="5.7505946150826E-07"
        ixy="-3.110319161842E-08"
        ixz="-2.480720386174E-13"
        iyy="2.76755087006631E-07"
        iyz="-7.5319951346526E-13"
        izz="4.58332065658862E-07" />
    </inertial>
    <visual>
      <origin
        xyz="0 0 0"
        rpy="0 0 0" />
      <geometry>
        <mesh
          filename="package://CLOVIS25_URDF_V1/meshes/Link72_AxisRy_PinkyKnucle_Flexion.STL" />
      </geometry>
      <material
        name="">
        <color
          rgba="0.752941176470588 0.752941176470588 0.752941176470588 1" />
      </material>
    </visual>
    <collision>
      <origin
        xyz="0 0 0"
        rpy="0 0 0" />
      <geometry>
        <mesh
          filename="package://CLOVIS25_URDF_V1/meshes/Link72_AxisRy_PinkyKnucle_Flexion.STL" />
      </geometry>
    </collision>
  </link>
  <joint
    name="R72_AxisRy_PinkyKnucle_Flexion"
    type="revolute">
    <origin
      xyz="0 0.0957999999999998 0.0238999999999999"
      rpy="0 0 0" />
    <parent
      link="Link36_AxisRy_Wrist_Flexion" />
    <child
      link="Link72_AxisRy_PinkyKnucle_Flexion" />
    <axis
      xyz="0 0 1" />
    <limit
      lower="0"
      upper="0"
      effort="0"
      velocity="0" />
  </joint>
  <link
    name="Link73_AxisRy_PinkyMiddle_Flexion">
    <inertial>
      <origin
        xyz="0.00240152083459458 0.00654385041930947 0.00892219951206391"
        rpy="0 0 0" />
      <mass
        value="0.00474922043263774" />
      <inertia
        ixx="3.87568218500717E-07"
        ixy="3.21643084330278E-08"
        ixz="1.59172343000488E-10"
        iyy="1.86351243809441E-07"
        iyz="7.10248735888814E-10"
        izz="3.03572936344066E-07" />
    </inertial>
    <visual>
      <origin
        xyz="0 0 0"
        rpy="0 0 0" />
      <geometry>
        <mesh
          filename="package://CLOVIS25_URDF_V1/meshes/Link73_AxisRy_PinkyMiddle_Flexion.STL" />
      </geometry>
      <material
        name="">
        <color
          rgba="0.752941176470588 0.752941176470588 0.752941176470588 1" />
      </material>
    </visual>
    <collision>
      <origin
        xyz="0 0 0"
        rpy="0 0 0" />
      <geometry>
        <mesh
          filename="package://CLOVIS25_URDF_V1/meshes/Link73_AxisRy_PinkyMiddle_Flexion.STL" />
      </geometry>
    </collision>
  </link>
  <joint
    name="R73_AxisRy_PinkyMiddle_Flexion"
    type="revolute">
    <origin
      xyz="0 0.0300000000000018 -0.000100000000000102"
      rpy="3.14159265358979 0 -3.14159265358979" />
    <parent
      link="Link72_AxisRy_PinkyKnucle_Flexion" />
    <child
      link="Link73_AxisRy_PinkyMiddle_Flexion" />
    <axis
      xyz="0 0 -1" />
    <limit
      lower="0"
      upper="0"
      effort="0"
      velocity="0" />
  </joint>
  <link
    name="Link74_AxisRy_PinkyTip_Flexion">
    <inertial>
      <origin
        xyz="-0.00555116931158159 0.00681823871640064 0.0089977810675173"
        rpy="0 0 0" />
      <mass
        value="0.00507656742740203" />
      <inertia
        ixx="2.56875396781832E-07"
        ixy="5.16043318849009E-08"
        ixz="1.45538017299538E-11"
        iyy="1.71402595011333E-07"
        iyz="-1.26272741803143E-10"
        izz="2.21265452728323E-07" />
    </inertial>
    <visual>
      <origin
        xyz="0 0 0"
        rpy="0 0 0" />
      <geometry>
        <mesh
          filename="package://CLOVIS25_URDF_V1/meshes/Link74_AxisRy_PinkyTip_Flexion.STL" />
      </geometry>
      <material
        name="">
        <color
          rgba="0.752941176470588 0.752941176470588 0.752941176470588 1" />
      </material>
    </visual>
    <collision>
      <origin
        xyz="0 0 0"
        rpy="0 0 0" />
      <geometry>
        <mesh
          filename="package://CLOVIS25_URDF_V1/meshes/Link74_AxisRy_PinkyTip_Flexion.STL" />
      </geometry>
    </collision>
  </link>
  <joint
    name="R74_AxisRy_PinkyTip_Flexion"
    type="revolute">
    <origin
      xyz="-0.000938526804098255 0.0189768060388994 -0.000100000000000005"
      rpy="0 0 0" />
    <parent
      link="Link73_AxisRy_PinkyMiddle_Flexion" />
    <child
      link="Link74_AxisRy_PinkyTip_Flexion" />
    <axis
      xyz="0 0 -1" />
    <limit
      lower="0"
      upper="0"
      effort="0"
      velocity="0" />
  </joint>
  <link
    name="Link40_AxisRy_Shoulder_Flexion">
    <inertial>
      <origin
        xyz="-0.0012112355865147 -0.0032505255283299 -0.0120546201899154"
        rpy="0 0 0" />
      <mass
        value="0.0372585040292267" />
      <inertia
        ixx="1.59292439557234E-05"
        ixy="-1.20796833868441E-06"
        ixz="4.79452740015106E-07"
        iyy="1.63936933583613E-05"
        iyz="8.02800974683717E-07"
        izz="2.0315299924828E-05" />
    </inertial>
    <visual>
      <origin
        xyz="0 0 0"
        rpy="0 0 0" />
      <geometry>
        <mesh
          filename="package://CLOVIS25_URDF_V1/meshes/Link40_AxisRy_Shoulder_Flexion.STL" />
      </geometry>
      <material
        name="">
        <color
          rgba="0.752941176470588 0.752941176470588 0.752941176470588 1" />
      </material>
    </visual>
    <collision>
      <origin
        xyz="0 0 0"
        rpy="0 0 0" />
      <geometry>
        <mesh
          filename="package://CLOVIS25_URDF_V1/meshes/Link40_AxisRy_Shoulder_Flexion.STL" />
      </geometry>
    </collision>
  </link>
  <joint
    name="R40_AxisRy_Shoulder_Flexion"
    type="revolute">
    <origin
      xyz="0.0289259399205682 0.101367916470833 0.130853241275273"
      rpy="-2.88891239844771 1.30019891167267 1.57079632679489" />
    <parent
      link="Link2_AxisRy_Abs_Pitch" />
    <child
      link="Link40_AxisRy_Shoulder_Flexion" />
    <axis
      xyz="0 0 1" />
    <limit
      lower="0"
      upper="0"
      effort="0"
      velocity="0" />
  </joint>
  <link
    name="Link41_AxisRz_Shoulder_Rotation">
    <inertial>
      <origin
        xyz="-0.031037590317066 0.0149616403812064 -0.00284732124355624"
        rpy="0 0 0" />
      <mass
        value="0.0306386900120499" />
      <inertia
        ixx="1.91180620203453E-05"
        ixy="2.8166310952451E-07"
        ixz="-8.43194947317034E-07"
        iyy="2.64926204617935E-05"
        iyz="-1.49808930781167E-07"
        izz="1.44968161981896E-05" />
    </inertial>
    <visual>
      <origin
        xyz="0 0 0"
        rpy="0 0 0" />
      <geometry>
        <mesh
          filename="package://CLOVIS25_URDF_V1/meshes/Link41_AxisRz_Shoulder_Rotation.STL" />
      </geometry>
      <material
        name="">
        <color
          rgba="0.752941176470588 0.752941176470588 0.752941176470588 1" />
      </material>
    </visual>
    <collision>
      <origin
        xyz="0 0 0"
        rpy="0 0 0" />
      <geometry>
        <mesh
          filename="package://CLOVIS25_URDF_V1/meshes/Link41_AxisRz_Shoulder_Rotation.STL" />
      </geometry>
    </collision>
  </link>
  <joint
    name="R41_AxisRz_Shoulder_Rotation"
    type="revolute">
    <origin
      xyz="0 0 -0.0185"
      rpy="-1.5707963267949 -1.31811607165281 1.5707963267949" />
    <parent
      link="Link40_AxisRy_Shoulder_Flexion" />
    <child
      link="Link41_AxisRz_Shoulder_Rotation" />
    <axis
      xyz="0 0 -1" />
    <limit
      lower="0"
      upper="0"
      effort="0"
      velocity="0" />
  </joint>
  <link
    name="Link42_AxisRx_Shoulder_Abduction">
    <inertial>
      <origin
        xyz="-0.0104533722346799 0.0621641528020337 -0.0367098346254359"
        rpy="0 0 0" />
      <mass
        value="0.102684755235716" />
      <inertia
        ixx="0.000190384776453776"
        ixy="3.56985271604809E-06"
        ixz="-8.38018790634231E-06"
        iyy="8.95074854552463E-05"
        iyz="1.36363520241324E-05"
        izz="0.000128462975361775" />
    </inertial>
    <visual>
      <origin
        xyz="0 0 0"
        rpy="0 0 0" />
      <geometry>
        <mesh
          filename="package://CLOVIS25_URDF_V1/meshes/Link42_AxisRx_Shoulder_Abduction.STL" />
      </geometry>
      <material
        name="">
        <color
          rgba="0.752941176470588 0.752941176470588 0.752941176470588 1" />
      </material>
    </visual>
    <collision>
      <origin
        xyz="0 0 0"
        rpy="0 0 0" />
      <geometry>
        <mesh
          filename="package://CLOVIS25_URDF_V1/meshes/Link42_AxisRx_Shoulder_Abduction.STL" />
      </geometry>
    </collision>
  </link>
  <joint
    name="R42_AxisRx_Shoulder_Abduction"
    type="revolute">
    <origin
      xyz="-0.0400000000000001 0.0349999999999999 0"
      rpy="-1.5707963267949 -0.270597415122226 0" />
    <parent
      link="Link41_AxisRz_Shoulder_Rotation" />
    <child
      link="Link42_AxisRx_Shoulder_Abduction" />
    <axis
      xyz="0 0 -1" />
    <limit
      lower="0"
      upper="0"
      effort="0"
      velocity="0" />
  </joint>
  <link
    name="Link43_AxisRy_Elbow_Flexion">
    <inertial>
      <origin
        xyz="-0.00807276875151361 -0.0218914502303467 3.10306755541001E-07"
        rpy="0 0 0" />
      <mass
        value="0.0625250264832972" />
      <inertia
        ixx="2.66478001692804E-05"
        ixy="6.31836851327582E-07"
        ixz="-1.39712764287424E-11"
        iyy="2.90856880879152E-05"
        iyz="-2.342485238318E-10"
        izz="2.16871103133531E-05" />
    </inertial>
    <visual>
      <origin
        xyz="0 0 0"
        rpy="0 0 0" />
      <geometry>
        <mesh
          filename="package://CLOVIS25_URDF_V1/meshes/Link43_AxisRy_Elbow_Flexion.STL" />
      </geometry>
      <material
        name="">
        <color
          rgba="0.752941176470588 0.752941176470588 0.752941176470588 1" />
      </material>
    </visual>
    <collision>
      <origin
        xyz="0 0 0"
        rpy="0 0 0" />
      <geometry>
        <mesh
          filename="package://CLOVIS25_URDF_V1/meshes/Link43_AxisRy_Elbow_Flexion.STL" />
      </geometry>
    </collision>
  </link>
  <joint
    name="R43_AxisRy_Elbow_Flexion"
    type="revolute">
    <origin
      xyz="-0.0113302416132193 0.129505311184469 -0.035"
      rpy="1.5707963267949 0 -1.48352986419519" />
    <parent
      link="Link42_AxisRx_Shoulder_Abduction" />
    <child
      link="Link43_AxisRy_Elbow_Flexion" />
    <axis
      xyz="0 0 1" />
    <limit
      lower="0"
      upper="0"
      effort="0"
      velocity="0" />
  </joint>
  <link
    name="Link44_AxisRz_Wrist_Rotation">
    <inertial>
      <origin
        xyz="-0.000520135717627684 0.000899444805753625 -0.0257687217825777"
        rpy="0 0 0" />
      <mass
        value="0.0957043837946211" />
      <inertia
        ixx="5.31198213772158E-05"
        ixy="4.22873938637666E-08"
        ixz="-1.80532675917179E-07"
        iyy="5.30300162858389E-05"
        iyz="1.14738316178829E-06"
        izz="3.79612077150448E-05" />
    </inertial>
    <visual>
      <origin
        xyz="0 0 0"
        rpy="0 0 0" />
      <geometry>
        <mesh
          filename="package://CLOVIS25_URDF_V1/meshes/Link44_AxisRz_Wrist_Rotation.STL" />
      </geometry>
      <material
        name="">
        <color
          rgba="0.752941176470588 0.752941176470588 0.752941176470588 1" />
      </material>
    </visual>
    <collision>
      <origin
        xyz="0 0 0"
        rpy="0 0 0" />
      <geometry>
        <mesh
          filename="package://CLOVIS25_URDF_V1/meshes/Link44_AxisRz_Wrist_Rotation.STL" />
      </geometry>
    </collision>
  </link>
  <joint
    name="R44_AxisRz_Wrist_Rotation"
    type="revolute">
    <origin
      xyz="-0.0399999999999999 -0.019 0"
      rpy="-1.57823976718433 1.57079631189374 -1.57823976718433" />
    <parent
      link="Link43_AxisRy_Elbow_Flexion" />
    <child
      link="Link44_AxisRz_Wrist_Rotation" />
    <axis
      xyz="0 0 -1" />
    <limit
      lower="0"
      upper="0"
      effort="0"
      velocity="0" />
  </joint>
  <link
    name="Link45_AxisRx_Wrist_Abduction">
    <inertial>
      <origin
        xyz="-0.0081343586336618 4.05206361998867E-07 5.46147071178726E-08"
        rpy="0 0 0" />
      <mass
        value="0.0129110778126473" />
      <inertia
        ixx="5.34580369587508E-06"
        ixy="-1.03772626655719E-10"
        ixz="-6.34307336185345E-11"
        iyy="1.41876387165847E-06"
        iyz="1.77315331870161E-11"
        izz="5.32098561653812E-06" />
    </inertial>
    <visual>
      <origin
        xyz="0 0 0"
        rpy="0 0 0" />
      <geometry>
        <mesh
          filename="package://CLOVIS25_URDF_V1/meshes/Link45_AxisRx_Wrist_Abduction.STL" />
      </geometry>
      <material
        name="">
        <color
          rgba="0.752941176470588 0.752941176470588 0.752941176470588 1" />
      </material>
    </visual>
    <collision>
      <origin
        xyz="0 0 0"
        rpy="0 0 0" />
      <geometry>
        <mesh
          filename="package://CLOVIS25_URDF_V1/meshes/Link45_AxisRx_Wrist_Abduction.STL" />
      </geometry>
    </collision>
  </link>
  <joint
    name="R45_AxisRx_Wrist_Abduction"
    type="revolute">
    <origin
      xyz="0 0 -0.0935"
      rpy="0 1.5707963267949 0" />
    <parent
      link="Link44_AxisRz_Wrist_Rotation" />
    <child
      link="Link45_AxisRx_Wrist_Abduction" />
    <axis
      xyz="0 0 -1" />
    <limit
      lower="0"
      upper="0"
      effort="0"
      velocity="0" />
  </joint>
  <link
    name="Link46_AxisRy_Wrist_Flexion">
    <inertial>
      <origin
        xyz="0.00278267075384758 0.0506979479143743 -0.000514721850256944"
        rpy="0 0 0" />
      <mass
        value="0.0948671737461925" />
      <inertia
        ixx="6.39852654912567E-05"
        ixy="-5.73654124478472E-06"
        ixz="-3.49417172570608E-06"
        iyy="2.95680935571864E-05"
        iyz="-7.83632804526931E-06"
        izz="4.67672378979347E-05" />
    </inertial>
    <visual>
      <origin
        xyz="0 0 0"
        rpy="0 0 0" />
      <geometry>
        <mesh
          filename="package://CLOVIS25_URDF_V1/meshes/Link46_AxisRy_Wrist_Flexion.STL" />
      </geometry>
      <material
        name="">
        <color
          rgba="0.752941176470588 0.752941176470588 0.752941176470588 1" />
      </material>
    </visual>
    <collision>
      <origin
        xyz="0 0 0"
        rpy="0 0 0" />
      <geometry>
        <mesh
          filename="package://CLOVIS25_URDF_V1/meshes/Link46_AxisRy_Wrist_Flexion.STL" />
      </geometry>
    </collision>
  </link>
  <joint
    name="R46_AxisRy_Wrist_Flexion"
    type="revolute">
    <origin
      xyz="0 0 0"
      rpy="1.5707963267949 1.48352986419519 0" />
    <parent
      link="Link45_AxisRx_Wrist_Abduction" />
    <child
      link="Link46_AxisRy_Wrist_Flexion" />
    <axis
      xyz="0 0 -1" />
    <limit
      lower="0"
      upper="0"
      effort="0"
      velocity="0" />
  </joint>
  <link
    name="Link61_AxisRz_ThumbKnucle_Rotation">
    <inertial>
      <origin
        xyz="4.91409246350383E-08 -0.000121891601797812 -0.00201210065266587"
        rpy="0 0 0" />
      <mass
        value="0.00115968038152585" />
      <inertia
        ixx="4.03439585123012E-08"
        ixy="2.39268724516423E-13"
        ixz="-3.87054840157486E-14"
        iyy="4.18267857957213E-08"
        iyz="4.02150632623849E-10"
        izz="1.66744809622366E-08" />
    </inertial>
    <visual>
      <origin
        xyz="0 0 0"
        rpy="0 0 0" />
      <geometry>
        <mesh
          filename="package://CLOVIS25_URDF_V1/meshes/Link61_AxisRz_ThumbKnucle_Rotation.STL" />
      </geometry>
      <material
        name="">
        <color
          rgba="0.752941176470588 0.752941176470588 0.752941176470588 1" />
      </material>
    </visual>
    <collision>
      <origin
        xyz="0 0 0"
        rpy="0 0 0" />
      <geometry>
        <mesh
          filename="package://CLOVIS25_URDF_V1/meshes/Link61_AxisRz_ThumbKnucle_Rotation.STL" />
      </geometry>
    </collision>
  </link>
  <joint
    name="R61_AxisRz_ThumbKnucle_Rotation"
    type="revolute">
    <origin
      xyz="-0.0208992160414363 0.0381999999999993 -0.0217863192850378"
      rpy="-1.5707963267949 0 0" />
    <parent
      link="Link46_AxisRy_Wrist_Flexion" />
    <child
      link="Link61_AxisRz_ThumbKnucle_Rotation" />
    <axis
      xyz="0 0 -1" />
    <limit
      lower="0"
      upper="0"
      effort="0"
      velocity="0" />
  </joint>
  <link
    name="Link62_AxisRy_ThumbKnucle_Flexion">
    <inertial>
      <origin
        xyz="0.00162052317270528 0.0143580240590543 8.87240710345516E-08"
        rpy="0 0 0" />
      <mass
        value="0.00310333576369737" />
      <inertia
        ixx="2.79345952527195E-07"
        ixy="-5.4569982727058E-08"
        ixz="1.93583934081484E-12"
        iyy="1.60619700743318E-07"
        iyz="1.82698794802282E-12"
        izz="2.38435467591382E-07" />
    </inertial>
    <visual>
      <origin
        xyz="0 0 0"
        rpy="0 0 0" />
      <geometry>
        <mesh
          filename="package://CLOVIS25_URDF_V1/meshes/Link62_AxisRy_ThumbKnucle_Flexion.STL" />
      </geometry>
      <material
        name="">
        <color
          rgba="0.752941176470588 0.752941176470588 0.752941176470588 1" />
      </material>
    </visual>
    <collision>
      <origin
        xyz="0 0 0"
        rpy="0 0 0" />
      <geometry>
        <mesh
          filename="package://CLOVIS25_URDF_V1/meshes/Link62_AxisRy_ThumbKnucle_Flexion.STL" />
      </geometry>
    </collision>
  </link>
  <joint
    name="R62_AxisRy_ThumbKnucle_Flexion"
    type="revolute">
    <origin
      xyz="0 0 0"
      rpy="3.14159265358979 -1.5707963267949 0" />
    <parent
      link="Link61_AxisRz_ThumbKnucle_Rotation" />
    <child
      link="Link62_AxisRy_ThumbKnucle_Flexion" />
    <axis
      xyz="0 0 -1" />
    <limit
      lower="0"
      upper="0"
      effort="0"
      velocity="0" />
  </joint>
  <link
    name="Link63_AxisRy_Thumb_Flexion">
    <inertial>
      <origin
        xyz="7.16902495705579E-05 0.00984633190078806 -0.000109122506530196"
        rpy="0 0 0" />
      <mass
        value="0.00389502563585409" />
      <inertia
        ixx="3.31740758410828E-07"
        ixy="8.5223461608592E-08"
        ixz="-3.0366512091661E-10"
        iyy="1.48960518802381E-07"
        iyz="8.31876939876061E-10"
        izz="3.11286681941716E-07" />
    </inertial>
    <visual>
      <origin
        xyz="0 0 0"
        rpy="0 0 0" />
      <geometry>
        <mesh
          filename="package://CLOVIS25_URDF_V1/meshes/Link63_AxisRy_Thumb_Flexion.STL" />
      </geometry>
      <material
        name="">
        <color
          rgba="0.752941176470588 0.752941176470588 0.752941176470588 1" />
      </material>
    </visual>
    <collision>
      <origin
        xyz="0 0 0"
        rpy="0 0 0" />
      <geometry>
        <mesh
          filename="package://CLOVIS25_URDF_V1/meshes/Link63_AxisRy_Thumb_Flexion.STL" />
      </geometry>
    </collision>
  </link>
  <joint
    name="R63_AxisRy_Thumb_Flexion"
    type="revolute">
    <origin
      xyz="0.00778918517667519 0.0289711683278997 -9.9999999999989E-05"
      rpy="-3.14159265358979 0 3.14159265358979" />
    <parent
      link="Link62_AxisRy_ThumbKnucle_Flexion" />
    <child
      link="Link63_AxisRy_Thumb_Flexion" />
    <axis
      xyz="0 0 -1" />
    <limit
      lower="0"
      upper="0"
      effort="0"
      velocity="0" />
  </joint>
  <link
    name="Link64_AxisRx_IndexKnucle_Abduction">
    <inertial>
      <origin
        xyz="-0.000121891601795154 -4.91409300751311E-08 -0.00201210065266336"
        rpy="0 0 0" />
      <mass
        value="0.00115968038152584" />
      <inertia
        ixx="4.18267857957159E-08"
        ixy="-2.39268724265425E-13"
        ixz="4.02150632622232E-10"
        iyy="4.03439585123047E-08"
        iyz="3.87054838940788E-14"
        izz="1.66744809622272E-08" />
    </inertial>
    <visual>
      <origin
        xyz="0 0 0"
        rpy="0 0 0" />
      <geometry>
        <mesh
          filename="package://CLOVIS25_URDF_V1/meshes/Link64_AxisRx_IndexKnucle_Abduction.STL" />
      </geometry>
      <material
        name="">
        <color
          rgba="0.752941176470588 0.752941176470588 0.752941176470588 1" />
      </material>
    </visual>
    <collision>
      <origin
        xyz="0 0 0"
        rpy="0 0 0" />
      <geometry>
        <mesh
          filename="package://CLOVIS25_URDF_V1/meshes/Link64_AxisRx_IndexKnucle_Abduction.STL" />
      </geometry>
    </collision>
  </link>
  <joint
    name="R64_AxisRx_IndexKnucle_Abduction"
    type="revolute">
    <origin
      xyz="0 0.100710889132455 -0.0300000000000013"
      rpy="-1.5707963267949 0 1.5707963267949" />
    <parent
      link="Link46_AxisRy_Wrist_Flexion" />
    <child
      link="Link64_AxisRx_IndexKnucle_Abduction" />
    <axis
      xyz="0 0 -1" />
    <limit
      lower="0"
      upper="0"
      effort="0"
      velocity="0" />
  </joint>
  <link
    name="Link65_AxisRy_IndexKnucle_Flexion">
    <inertial>
      <origin
        xyz="-0.00211406335376799 0.0145062489951183 -4.40290206377147E-09"
        rpy="0 0 0" />
      <mass
        value="0.00305079596232101" />
      <inertia
        ixx="2.87529730754108E-07"
        ixy="-1.55515958091809E-08"
        ixz="-1.24036018612614E-13"
        iyy="1.38377543503227E-07"
        iyz="-3.76599757361595E-13"
        izz="2.29166032829321E-07" />
    </inertial>
    <visual>
      <origin
        xyz="0 0 0"
        rpy="0 0 0" />
      <geometry>
        <mesh
          filename="package://CLOVIS25_URDF_V1/meshes/Link65_AxisRy_IndexKnucle_Flexion.STL" />
      </geometry>
      <material
        name="">
        <color
          rgba="0.752941176470588 0.752941176470588 0.752941176470588 1" />
      </material>
    </visual>
    <collision>
      <origin
        xyz="0 0 0"
        rpy="0 0 0" />
      <geometry>
        <mesh
          filename="package://CLOVIS25_URDF_V1/meshes/Link65_AxisRy_IndexKnucle_Flexion.STL" />
      </geometry>
    </collision>
  </link>
  <joint
    name="R65_AxisRy_IndexKnucle_Flexion"
    type="fixed">
    <origin
      xyz="0 0 0"
      rpy="1.5707963267949 -1.5707963267949 0" />
    <parent
      link="Link64_AxisRx_IndexKnucle_Abduction" />
    <child
      link="Link65_AxisRy_IndexKnucle_Flexion" />
    <axis
      xyz="0 0 0" />
  </joint>
  <link
    name="Link66_AxisRy_IndexMiddle_Flexion">
    <inertial>
      <origin
        xyz="0.00240152083460476 0.00654385041930641 -7.78004879370062E-05"
        rpy="0 0 0" />
      <mass
        value="0.00237461021631886" />
      <inertia
        ixx="1.93784109250359E-07"
        ixy="1.60821542165126E-08"
        ixz="7.95861715000415E-11"
        iyy="9.31756219047256E-08"
        iyz="3.55124367944564E-10"
        izz="1.51786468172039E-07" />
    </inertial>
    <visual>
      <origin
        xyz="0 0 0"
        rpy="0 0 0" />
      <geometry>
        <mesh
          filename="package://CLOVIS25_URDF_V1/meshes/Link66_AxisRy_IndexMiddle_Flexion.STL" />
      </geometry>
      <material
        name="">
        <color
          rgba="0.752941176470588 0.752941176470588 0.752941176470588 1" />
      </material>
    </visual>
    <collision>
      <origin
        xyz="0 0 0"
        rpy="0 0 0" />
      <geometry>
        <mesh
          filename="package://CLOVIS25_URDF_V1/meshes/Link66_AxisRy_IndexMiddle_Flexion.STL" />
      </geometry>
    </collision>
  </link>
  <joint
    name="R66_AxisRy_IndexMiddle_Flexion"
    type="revolute">
    <origin
      xyz="0 0.0300000000000014 -9.99999999971579E-05"
      rpy="3.14159265358979 0 -3.14159265358979" />
    <parent
      link="Link65_AxisRy_IndexKnucle_Flexion" />
    <child
      link="Link66_AxisRy_IndexMiddle_Flexion" />
    <axis
      xyz="0 0 -1" />
    <limit
      lower="0"
      upper="0"
      effort="0"
      velocity="0" />
  </joint>
  <link
    name="Link67_AxisRy_IndexTip_Flexion">
    <inertial>
      <origin
        xyz="-0.00555116931157287 0.00681823871639811 -2.21893247968202E-06"
        rpy="0 0 0" />
      <mass
        value="0.00253828371370103" />
      <inertia
        ixx="1.28437698390917E-07"
        ixy="2.58021659424467E-08"
        ixz="7.2769008649899E-12"
        iyy="8.57012975056679E-08"
        iyz="-6.31363709015446E-11"
        izz="1.10632726364164E-07" />
    </inertial>
    <visual>
      <origin
        xyz="0 0 0"
        rpy="0 0 0" />
      <geometry>
        <mesh
          filename="package://CLOVIS25_URDF_V1/meshes/Link67_AxisRy_IndexTip_Flexion.STL" />
      </geometry>
      <material
        name="">
        <color
          rgba="0.752941176470588 0.752941176470588 0.752941176470588 1" />
      </material>
    </visual>
    <collision>
      <origin
        xyz="0 0 0"
        rpy="0 0 0" />
      <geometry>
        <mesh
          filename="package://CLOVIS25_URDF_V1/meshes/Link67_AxisRy_IndexTip_Flexion.STL" />
      </geometry>
    </collision>
  </link>
  <joint
    name="R67_AxisRy_IndexTip_Flexion"
    type="revolute">
    <origin
      xyz="-0.000938526804089929 0.0189768060388912 -9.99999999971579E-05"
      rpy="0 0 0" />
    <parent
      link="Link66_AxisRy_IndexMiddle_Flexion" />
    <child
      link="Link67_AxisRy_IndexTip_Flexion" />
    <axis
      xyz="0 0 -1" />
    <limit
      lower="0"
      upper="0"
      effort="0"
      velocity="0" />
  </joint>
  <link
    name="Link68_AxisRy_MiddleFingerKnucle_Flexion">
    <inertial>
      <origin
        xyz="-0.00211406335376796 0.0145062489951181 -4.40290677528044E-09"
        rpy="0 0 0" />
      <mass
        value="0.003050795962321" />
      <inertia
        ixx="2.875297307541E-07"
        ixy="-1.55515958091748E-08"
        ixz="-1.24036018409523E-13"
        iyy="1.38377543503217E-07"
        iyz="-3.76599757050423E-13"
        izz="2.29166032829304E-07" />
    </inertial>
    <visual>
      <origin
        xyz="0 0 0"
        rpy="0 0 0" />
      <geometry>
        <mesh
          filename="package://CLOVIS25_URDF_V1/meshes/Link68_AxisRy_MiddleFingerKnucle_Flexion.STL" />
      </geometry>
      <material
        name="">
        <color
          rgba="0.752941176470588 0.752941176470588 0.752941176470588 1" />
      </material>
    </visual>
    <collision>
      <origin
        xyz="0 0 0"
        rpy="0 0 0" />
      <geometry>
        <mesh
          filename="package://CLOVIS25_URDF_V1/meshes/Link68_AxisRy_MiddleFingerKnucle_Flexion.STL" />
      </geometry>
    </collision>
  </link>
  <joint
    name="R68_AxisRy_MiddleFingerKnucle_Flexion"
    type="revolute">
    <origin
      xyz="0 0.0958000000000002 -0.012145230173743"
      rpy="-3.14159265358979 0 -3.14159265358979" />
    <parent
      link="Link46_AxisRy_Wrist_Flexion" />
    <child
      link="Link68_AxisRy_MiddleFingerKnucle_Flexion" />
    <axis
      xyz="0 0 -1" />
    <limit
      lower="0"
      upper="0"
      effort="0"
      velocity="0" />
  </joint>
  <link
    name="Link69_AxisRy_MiddleFingerMiddle_Flexion">
    <inertial>
      <origin
        xyz="0.0024015208346044 0.00654385041930691 -7.78004879364545E-05"
        rpy="0 0 0" />
      <mass
        value="0.00237461021631886" />
      <inertia
        ixx="1.93784109250358E-07"
        ixy="1.60821542165147E-08"
        ixz="7.95861715001935E-11"
        iyy="9.31756219047187E-08"
        iyz="3.55124367944328E-10"
        izz="1.51786468172031E-07" />
    </inertial>
    <visual>
      <origin
        xyz="0 0 0"
        rpy="0 0 0" />
      <geometry>
        <mesh
          filename="package://CLOVIS25_URDF_V1/meshes/Link69_AxisRy_MiddleFingerMiddle_Flexion.STL" />
      </geometry>
      <material
        name="">
        <color
          rgba="0.752941176470588 0.752941176470588 0.752941176470588 1" />
      </material>
    </visual>
    <collision>
      <origin
        xyz="0 0 0"
        rpy="0 0 0" />
      <geometry>
        <mesh
          filename="package://CLOVIS25_URDF_V1/meshes/Link69_AxisRy_MiddleFingerMiddle_Flexion.STL" />
      </geometry>
    </collision>
  </link>
  <joint
    name="R69_AxisRy_MiddleFingerMiddle_Flexion"
    type="revolute">
    <origin
      xyz="0 0.0299999999999988 -9.99999999982022E-05"
      rpy="-3.14159265358979 0 3.14159265358979" />
    <parent
      link="Link68_AxisRy_MiddleFingerKnucle_Flexion" />
    <child
      link="Link69_AxisRy_MiddleFingerMiddle_Flexion" />
    <axis
      xyz="0 0 -1" />
    <limit
      lower="0"
      upper="0"
      effort="0"
      velocity="0" />
  </joint>
  <link
    name="Link81_AxisRy_MiddleFingerTip_Flexion">
    <inertial>
      <origin
        xyz="0.00555116931157487 -0.00681823871639956 -2.21893247968549E-06"
        rpy="0 0 0" />
      <mass
        value="0.00253828371370102" />
      <inertia
        ixx="1.28437698390917E-07"
        ixy="2.58021659424493E-08"
        ixz="-7.27690086497009E-12"
        iyy="8.5701297505671E-08"
        iyz="6.31363709016221E-11"
        izz="1.10632726364166E-07" />
    </inertial>
    <visual>
      <origin
        xyz="0 0 0"
        rpy="0 0 0" />
      <geometry>
        <mesh
          filename="package://CLOVIS25_URDF_V1/meshes/Link81_AxisRy_MiddleFingerTip_Flexion.STL" />
      </geometry>
      <material
        name="">
        <color
          rgba="0.752941176470588 0.752941176470588 0.752941176470588 1" />
      </material>
    </visual>
    <collision>
      <origin
        xyz="0 0 0"
        rpy="0 0 0" />
      <geometry>
        <mesh
          filename="package://CLOVIS25_URDF_V1/meshes/Link81_AxisRy_MiddleFingerTip_Flexion.STL" />
      </geometry>
    </collision>
  </link>
  <joint
    name="R81_AxisRy_MiddleFingerTip_Flexion"
    type="revolute">
    <origin
      xyz="-0.000938526804097034 0.0189768060388982 -9.99999999987781E-05"
      rpy="0 0 -3.14159265358979" />
    <parent
      link="Link69_AxisRy_MiddleFingerMiddle_Flexion" />
    <child
      link="Link81_AxisRy_MiddleFingerTip_Flexion" />
    <axis
      xyz="0 0 -1" />
    <limit
      lower="0"
      upper="0"
      effort="0"
      velocity="0" />
  </joint>
  <link
    name="Link82_AxisRy_PinkyKnucle_Flexion">
    <inertial>
      <origin
        xyz="-0.0021140633537679 0.0145062489951181 0.0089999955970932"
        rpy="0 0 0" />
      <mass
        value="0.00610159192464206" />
      <inertia
        ixx="5.75059461508254E-07"
        ixy="-3.11031916184132E-08"
        ixz="-2.48072038098343E-13"
        iyy="2.7675508700658E-07"
        iyz="-7.53199513729181E-13"
        izz="4.58332065658804E-07" />
    </inertial>
    <visual>
      <origin
        xyz="0 0 0"
        rpy="0 0 0" />
      <geometry>
        <mesh
          filename="package://CLOVIS25_URDF_V1/meshes/Link82_AxisRy_PinkyKnucle_Flexion.STL" />
      </geometry>
      <material
        name="">
        <color
          rgba="0.752941176470588 0.752941176470588 0.752941176470588 1" />
      </material>
    </visual>
    <collision>
      <origin
        xyz="0 0 0"
        rpy="0 0 0" />
      <geometry>
        <mesh
          filename="package://CLOVIS25_URDF_V1/meshes/Link82_AxisRy_PinkyKnucle_Flexion.STL" />
      </geometry>
    </collision>
  </link>
  <joint
    name="R82_AxisRy_PinkyKnucle_Flexion"
    type="revolute">
    <origin
      xyz="0 0.0958000000000002 0.0238547698262569"
      rpy="-3.14159265358979 0 -3.14159265358979" />
    <parent
      link="Link46_AxisRy_Wrist_Flexion" />
    <child
      link="Link82_AxisRy_PinkyKnucle_Flexion" />
    <axis
      xyz="0 0 -1" />
    <limit
      lower="0"
      upper="0"
      effort="0"
      velocity="0" />
  </joint>
  <link
    name="Link83_AxisRy_PinkyMiddle_Flexion">
    <inertial>
      <origin
        xyz="0.00240152083460407 0.00654385041930974 0.00892219951205621"
        rpy="0 0 0" />
      <mass
        value="0.00474922043263773" />
      <inertia
        ixx="3.87568218500722E-07"
        ixy="3.21643084330257E-08"
        ixz="1.59172343000947E-10"
        iyy="1.86351243809437E-07"
        iyz="7.10248735888105E-10"
        izz="3.03572936344067E-07" />
    </inertial>
    <visual>
      <origin
        xyz="0 0 0"
        rpy="0 0 0" />
      <geometry>
        <mesh
          filename="package://CLOVIS25_URDF_V1/meshes/Link83_AxisRy_PinkyMiddle_Flexion.STL" />
      </geometry>
      <material
        name="">
        <color
          rgba="0.752941176470588 0.752941176470588 0.752941176470588 1" />
      </material>
    </visual>
    <collision>
      <origin
        xyz="0 0 0"
        rpy="0 0 0" />
      <geometry>
        <mesh
          filename="package://CLOVIS25_URDF_V1/meshes/Link83_AxisRy_PinkyMiddle_Flexion.STL" />
      </geometry>
    </collision>
  </link>
  <joint
    name="R83_AxisRy_PinkyMiddle_Flexion"
    type="revolute">
    <origin
      xyz="0 0.03 0.0179"
      rpy="-3.1416 0 3.1416" />
    <parent
      link="Link82_AxisRy_PinkyKnucle_Flexion" />
    <child
      link="Link83_AxisRy_PinkyMiddle_Flexion" />
    <axis
      xyz="0 0 -1" />
    <limit
      lower="0"
      upper="0"
      effort="0"
      velocity="0" />
  </joint>
  <link
    name="Link84_AxisRy_PinkyTip_Flexion">
    <inertial>
      <origin
        xyz="-0.00555116931157468 0.00681823871640208 0.00899778106751429"
        rpy="0 0 0" />
      <mass
        value="0.00507656742740203" />
      <inertia
        ixx="2.56875396781835E-07"
        ixy="5.16043318848952E-08"
        ixz="1.45538017299111E-11"
        iyy="1.71402595011341E-07"
        iyz="-1.26272741802829E-10"
        izz="2.21265452728333E-07" />
    </inertial>
    <visual>
      <origin
        xyz="0 0 0"
        rpy="0 0 0" />
      <geometry>
        <mesh
          filename="package://CLOVIS25_URDF_V1/meshes/Link84_AxisRy_PinkyTip_Flexion.STL" />
      </geometry>
      <material
        name="">
        <color
          rgba="0.752941176470588 0.752941176470588 0.752941176470588 1" />
      </material>
    </visual>
    <collision>
      <origin
        xyz="0 0 0"
        rpy="0 0 0" />
      <geometry>
        <mesh
          filename="package://CLOVIS25_URDF_V1/meshes/Link84_AxisRy_PinkyTip_Flexion.STL" />
      </geometry>
    </collision>
  </link>
  <joint
    name="R84_AxisRy_PinkyTip_Flexion"
    type="revolute">
    <origin
      xyz="-0.00093853 0.018977 -0.0001"
      rpy="0 0 0" />
    <parent
      link="Link83_AxisRy_PinkyMiddle_Flexion" />
    <child
      link="Link84_AxisRy_PinkyTip_Flexion" />
    <axis
      xyz="0 0 -1" />
    <limit
      lower="0"
      upper="0"
      effort="0"
      velocity="0" />
  </joint>
  <link
    name="Link10_AxisRy_Hips_Flexion">
    <inertial>
      <origin
        xyz="-0.0354918587362039 0.000913918322320433 0.018194719601768"
        rpy="0 0 0" />
      <mass
        value="0.154615097187712" />
      <inertia
        ixx="0.000129284073057894"
        ixy="5.95413093632E-06"
        ixz="-4.7324372337435E-06"
        iyy="0.000183034354985312"
        iyz="5.32228933808357E-06"
        izz="7.52482691085156E-05" />
    </inertial>
    <visual>
      <origin
        xyz="0 0 0"
        rpy="0 0 0" />
      <geometry>
        <mesh
          filename="package://CLOVIS25_URDF_V1/meshes/Link10_AxisRy_Hips_Flexion.STL" />
      </geometry>
      <material
        name="">
        <color
          rgba="0.752941176470588 0.752941176470588 0.752941176470588 1" />
      </material>
    </visual>
    <collision>
      <origin
        xyz="0 0 0"
        rpy="0 0 0" />
      <geometry>
        <mesh
          filename="package://CLOVIS25_URDF_V1/meshes/Link10_AxisRy_Hips_Flexion.STL" />
      </geometry>
    </collision>
  </link>
  <joint
    name="R10_AxisRy_Hips_Flexion"
    type="revolute">
    <origin
      xyz="0.058997 0 -0.036813"
      rpy="0 -0.5236 3.1416" />
    <parent
      link="base_link_R0_HipsWaist_Yaw" />
    <child
      link="Link10_AxisRy_Hips_Flexion" />
    <axis
      xyz="-1 0 0" />
    <limit
      lower="-1.396"
      upper="1.396"
      effort="3.66"
      velocity="5.05" />
  </joint>
  <link
    name="Link11_AxisRx_Hips_Abduction">
    <inertial>
      <origin
        xyz="-0.000420686937343747 -0.0141524399660883 0.0464372807980134"
        rpy="0 0 0" />
      <mass
        value="0.168812815651825" />
      <inertia
        ixx="0.000116232359472686"
        ixy="-3.412862720292E-06"
        ixz="-2.94169778032604E-06"
        iyy="0.000163337696614815"
        iyz="-2.5591877488419E-05"
        izz="0.000177818098522985" />
    </inertial>
    <visual>
      <origin
        xyz="0 0 0"
        rpy="0 0 0" />
      <geometry>
        <mesh
          filename="package://CLOVIS25_URDF_V1/meshes/Link11_AxisRx_Hips_Abduction.STL" />
      </geometry>
      <material
        name="">
        <color
          rgba="0.752941176470588 0.752941176470588 0.752941176470588 1" />
      </material>
    </visual>
    <collision>
      <origin
        xyz="0 0 0"
        rpy="0 0 0" />
      <geometry>
        <mesh
          filename="package://CLOVIS25_URDF_V1/meshes/Link11_AxisRx_Hips_Abduction.STL" />
      </geometry>
    </collision>
  </link>
  <joint
    name="R11_AxisRx_Hips_Abduction"
    type="revolute">
    <origin
      xyz="-0.0395 0 0"
      rpy="3.14159265358979 0 1.5707963267949" />
    <parent
      link="Link10_AxisRy_Hips_Flexion" />
    <child
      link="Link11_AxisRx_Hips_Abduction" />
    <axis
      xyz="1 0 0" />
    <limit
      lower="-0.436"
      upper="1.047"
      effort="3.66"
      velocity="5.05" />
  </joint>
  <link
    name="Link12_AxisRz_Hips_Rotation">
    <inertial>
      <origin
        xyz="0.0299865209861309 0.000915006997890072 0.0395840914056426"
        rpy="0 0 0" />
      <mass
        value="0.308889411658998" />
      <inertia
        ixx="0.000258352042230296"
        ixy="-1.2017985889604E-05"
        ixz="-2.22319994912742E-05"
        iyy="0.000446775467584485"
        iyz="2.53945341205689E-05"
        izz="0.00029936684325554" />
    </inertial>
    <visual>
      <origin
        xyz="0 0 0"
        rpy="0 0 0" />
      <geometry>
        <mesh
          filename="package://CLOVIS25_URDF_V1/meshes/Link12_AxisRz_Hips_Rotation.STL" />
      </geometry>
      <material
        name="">
        <color
          rgba="0.752941176470588 0.752941176470588 0.752941176470588 1" />
      </material>
    </visual>
    <collision>
      <origin
        xyz="0 0 0"
        rpy="0 0 0" />
      <geometry>
        <mesh
          filename="package://CLOVIS25_URDF_V1/meshes/Link12_AxisRz_Hips_Rotation.STL" />
      </geometry>
    </collision>
  </link>
  <joint
    name="R12_AxisRz_Hips_Rotation"
    type="revolute">
    <origin
      xyz="0.000499999999999946 -0.0407499999999995 0.0705810704084321"
      rpy="-0.523598775598292 0 3.14159265358979" />
    <parent
      link="Link11_AxisRx_Hips_Abduction" />
    <child
      link="Link12_AxisRz_Hips_Rotation" />
    <axis
      xyz="0 0 -1" />
    <limit
      lower="-1.222"
      upper="1.571"
      effort="3.66"
      velocity="5.05" />
  </joint>
  <link
    name="Link13_AxisRy_Knee_Flexion">
    <inertial>
      <origin
        xyz="-0.00996165884627893 -3.95525887098014E-07 -0.0737094687999738"
        rpy="0 0 0" />
      <mass
        value="0.20810093518798" />
      <inertia
        ixx="0.000251269487093237"
        ixy="8.57301270406751E-11"
        ixz="5.37344393723943E-06"
        iyy="0.000240506181571732"
        iyz="1.05076278008497E-09"
        izz="7.36271056526115E-05" />
    </inertial>
    <visual>
      <origin
        xyz="0 0 0"
        rpy="0 0 0" />
      <geometry>
        <mesh
          filename="package://CLOVIS25_URDF_V1/meshes/Link13_AxisRy_Knee_Flexion.STL" />
      </geometry>
      <material
        name="">
        <color
          rgba="0.752941176470588 0.752941176470588 0.752941176470588 1" />
      </material>
    </visual>
    <collision>
      <origin
        xyz="0 0 0"
        rpy="0 0 0" />
      <geometry>
        <mesh
          filename="package://CLOVIS25_URDF_V1/meshes/Link13_AxisRy_Knee_Flexion.STL" />
      </geometry>
    </collision>
  </link>
  <joint
    name="R13_AxisRy_Knee_Flexion"
    type="revolute">
    <origin
      xyz="0 0 0.036"
      rpy="3.14159265358979 0 -3.14159265358979" />
    <parent
      link="Link12_AxisRz_Hips_Rotation" />
    <child
      link="Link13_AxisRy_Knee_Flexion" />
    <axis
      xyz="0 -1 0" />
    <limit
      lower="0"
      upper="2.094"
      effort="3.66"
      velocity="5.05" />
  </joint>
  <link
    name="Link14_AxisRy_Ankle_Flexion">
    <inertial>
      <origin
        xyz="4.88789106048614E-05 -4.22901893060157E-07 -0.000941696331463682"
        rpy="0 0 0" />
      <mass
        value="0.0198828974134902" />
      <inertia
        ixx="5.33136120702503E-06"
        ixy="5.67526433345648E-11"
        ixz="6.76121728274562E-09"
        iyy="3.84427573974655E-06"
        iyz="4.02949645322749E-12"
        izz="8.29733415735585E-06" />
    </inertial>
    <visual>
      <origin
        xyz="0 0 0"
        rpy="0 0 0" />
      <geometry>
        <mesh
          filename="package://CLOVIS25_URDF_V1/meshes/Link14_AxisRy_Ankle_Flexion.STL" />
      </geometry>
      <material
        name="">
        <color
          rgba="0.752941176470588 0.752941176470588 0.752941176470588 1" />
      </material>
    </visual>
    <collision>
      <origin
        xyz="0 0 0"
        rpy="0 0 0" />
      <geometry>
        <mesh
          filename="package://CLOVIS25_URDF_V1/meshes/Link14_AxisRy_Ankle_Flexion.STL" />
      </geometry>
    </collision>
  </link>
  <joint
    name="R14_AxisRy_Ankle_Flexion"
    type="revolute">
    <origin
      xyz="0 0 -0.14"
      rpy="0 0 0" />
    <parent
      link="Link13_AxisRy_Knee_Flexion" />
    <child
      link="Link14_AxisRy_Ankle_Flexion" />
    <axis
      xyz="0 1 0" />
    <limit
      lower="-0.96"
      upper="0.698"
      effort="3.66"
      velocity="5.05" />
  </joint>
  <link
    name="Link15_AxisRx_Ankle_Abduction">
    <inertial>
      <origin
        xyz="-0.00749525839369284 -1.00190964677505E-07 -0.0413958069840309"
        rpy="0 0 0" />
      <mass
        value="0.162069791623735" />
      <inertia
        ixx="8.37583833186822E-05"
        ixy="9.35731632652226E-11"
        ixz="5.76979843466876E-06"
        iyy="0.000111745804529979"
        iyz="5.47643800035808E-10"
        izz="0.000127010438609889" />
    </inertial>
    <visual>
      <origin
        xyz="0 0 0"
        rpy="0 0 0" />
      <geometry>
        <mesh
          filename="package://CLOVIS25_URDF_V1/meshes/Link15_AxisRx_Ankle_Abduction.STL" />
      </geometry>
      <material
        name="">
        <color
          rgba="0.752941176470588 0.752941176470588 0.752941176470588 1" />
      </material>
    </visual>
    <collision>
      <origin
        xyz="0 0 0"
        rpy="0 0 0" />
      <geometry>
        <mesh
          filename="package://CLOVIS25_URDF_V1/meshes/Link15_AxisRx_Ankle_Abduction.STL" />
      </geometry>
    </collision>
  </link>
  <joint
    name="R15_AxisRx_Ankle_Abduction"
    type="revolute">
    <origin
      xyz="0 0 0"
      rpy="0 0 -3.14159265358979" />
    <parent
      link="Link14_AxisRy_Ankle_Flexion" />
    <child
      link="Link15_AxisRx_Ankle_Abduction" />
    <axis
      xyz="1 0 0" />
    <limit
      lower="-0.96"
      upper="0.96"
      effort="3.66"
      velocity="5.05" />
  </joint>
  <link
    name="Link16_AxisRx_Toe_Flexion">
    <inertial>
      <origin
        xyz="0.0181977115240334 0.00126288994199183 -0.00954659053967727"
        rpy="0 0 0" />
      <mass
        value="0.0664189830579756" />
      <inertia
        ixx="3.9575421565876E-05"
        ixy="-1.39838716866601E-06"
        ixz="4.60537840513916E-06"
        iyy="2.8704941619012E-05"
        iyz="-1.28510150087997E-07"
        izz="5.6352915404693E-05" />
    </inertial>
    <visual>
      <origin
        xyz="0 0 0"
        rpy="0 0 0" />
      <geometry>
        <mesh
          filename="package://CLOVIS25_URDF_V1/meshes/Link16_AxisRx_Toe_Flexion.STL" />
      </geometry>
      <material
        name="">
        <color
          rgba="0.752941176470588 0.752941176470588 0.752941176470588 1" />
      </material>
    </visual>
    <collision>
      <origin
        xyz="0 0 0"
        rpy="0 0 0" />
      <geometry>
        <mesh
          filename="package://CLOVIS25_URDF_V1/meshes/Link16_AxisRx_Toe_Flexion.STL" />
      </geometry>
    </collision>
  </link>
  <joint
    name="R16_AxisRx_Toe_Flexion"
    type="revolute">
    <origin
      xyz="0.055 0 -0.0425"
      rpy="0 0 0" />
    <parent
      link="Link15_AxisRx_Ankle_Abduction" />
    <child
      link="Link16_AxisRx_Toe_Flexion" />
    <axis
      xyz="0 1 0" />
    <limit
      lower="-0.785"
      upper="0"
      effort="0.44"
      velocity="5.05" />
  </joint>
  <link
    name="Link20_AxisRy_Hips_Flexion">
    <inertial>
      <origin
        xyz="-0.0191695238748907 -0.00104952349483889 -0.0352473021715193"
        rpy="0 0 0" />
      <mass
        value="0.150034857109824" />
      <inertia
        ixx="7.41467834211886E-05"
        ixy="4.27066915988223E-06"
        ixz="4.19048433769202E-06"
        iyy="0.000175384510459711"
        iyz="-5.87188592248189E-06"
        izz="0.000122352676232008" />
    </inertial>
    <visual>
      <origin
        xyz="0 0 0"
        rpy="0 0 0" />
      <geometry>
        <mesh
          filename="package://CLOVIS25_URDF_V1/meshes/Link20_AxisRy_Hips_Flexion.STL" />
      </geometry>
      <material
        name="">
        <color
          rgba="0.752941176470588 0.752941176470588 0.752941176470588 1" />
      </material>
    </visual>
    <collision>
      <origin
        xyz="0 0 0"
        rpy="0 0 0" />
      <geometry>
        <mesh
          filename="package://CLOVIS25_URDF_V1/meshes/Link20_AxisRy_Hips_Flexion.STL" />
      </geometry>
    </collision>
  </link>
  <joint
    name="R20_AxisRy_Hips_Flexion"
    type="revolute">
    <origin
      xyz="-0.0589974226119289 0 -0.0368134665205265"
      rpy="0 1.0471975511966 0" />
    <parent
      link="base_link_R0_HipsWaist_Yaw" />
    <child
      link="Link20_AxisRy_Hips_Flexion" />
    <axis
      xyz="0 0 1" />
    <limit
      lower="-1.396"
      upper="1.396"
      effort="3.66"
      velocity="5.05" />
  </joint>
  <link
    name="Link21_AxisRx_Hips_Abduction">
    <inertial>
      <origin
        xyz="0.000421585960770148 -0.0109610923852847 -0.0472922255513191"
        rpy="0 0 0" />
      <mass
        value="0.168809122055464" />
      <inertia
        ixx="0.000116232144999569"
        ixy="-4.42363621138768E-06"
        ixz="-8.40343454054988E-07"
        iyy="0.000144789714142267"
        iyz="-6.52548921967783E-06"
        izz="0.000196356223785667" />
    </inertial>
    <visual>
      <origin
        xyz="0 0 0"
        rpy="0 0 0" />
      <geometry>
        <mesh
          filename="package://CLOVIS25_URDF_V1/meshes/Link21_AxisRx_Hips_Abduction.STL" />
      </geometry>
      <material
        name="">
        <color
          rgba="0.752941176470588 0.752941176470588 0.752941176470588 1" />
      </material>
    </visual>
    <collision>
      <origin
        xyz="0 0 0"
        rpy="0 0 0" />
      <geometry>
        <mesh
          filename="package://CLOVIS25_URDF_V1/meshes/Link21_AxisRx_Hips_Abduction.STL" />
      </geometry>
    </collision>
  </link>
  <joint
    name="R21_AxisRx_Hips_Abduction"
    type="revolute">
    <origin
      xyz="0 0 -0.0395000000000001"
      rpy="-1.0471975511966 0 1.5707963267949" />
    <parent
      link="Link20_AxisRy_Hips_Flexion" />
    <child
      link="Link21_AxisRx_Hips_Abduction" />
    <axis
      xyz="-1 0 0" />
    <limit
      lower="-0.436"
      upper="1.047"
      effort="3.66"
      velocity="5.05" />
  </joint>
  <link
    name="Link22_AxisRz_Hips_Rotation">
    <inertial>
      <origin
        xyz="0.029986627747195 -0.00091335149527208 0.0395841441494068"
        rpy="0 0 0" />
      <mass
        value="0.308888997867295" />
      <inertia
        ixx="0.000258350925683758"
        ixy="1.20182401297498E-05"
        ixz="-2.22308950799236E-05"
        iyy="0.000446773838832807"
        iyz="-2.53944021702722E-05"
        izz="0.000299365015684185" />
    </inertial>
    <visual>
      <origin
        xyz="0 0 0"
        rpy="0 0 0" />
      <geometry>
        <mesh
          filename="package://CLOVIS25_URDF_V1/meshes/Link22_AxisRz_Hips_Rotation.STL" />
      </geometry>
      <material
        name="">
        <color
          rgba="0.752941176470588 0.752941176470588 0.752941176470588 1" />
      </material>
    </visual>
    <collision>
      <origin
        xyz="0 0 0"
        rpy="0 0 0" />
      <geometry>
        <mesh
          filename="package://CLOVIS25_URDF_V1/meshes/Link22_AxisRz_Hips_Rotation.STL" />
      </geometry>
    </collision>
  </link>
  <joint
    name="R22_AxisRz_Hips_Rotation"
    type="revolute">
    <origin
      xyz="-0.000500000000000035 0 -0.0815000000000001"
      rpy="3.14159265358979 0 0" />
    <parent
      link="Link21_AxisRx_Hips_Abduction" />
    <child
      link="Link22_AxisRz_Hips_Rotation" />
    <axis
      xyz="0 0 -1" />
    <limit
      lower="-1.222"
      upper="1.571"
      effort="3.66"
      velocity="5.05" />
  </joint>
  <link
    name="Link23_AxisRy_Knee_Flexion">
    <inertial>
      <origin
        xyz="0.00996165887106264 3.9516013140839E-07 -0.0737094687119398"
        rpy="0 0 0" />
      <mass
        value="0.208100936749785" />
      <inertia
        ixx="0.000251269487849733"
        ixy="8.58282832171972E-11"
        ixz="-5.37344399964975E-06"
        iyy="0.000240506181810468"
        iyz="-1.05041562420194E-09"
        izz="7.3627106205833E-05" />
    </inertial>
    <visual>
      <origin
        xyz="0 0 0"
        rpy="0 0 0" />
      <geometry>
        <mesh
          filename="package://CLOVIS25_URDF_V1/meshes/Link23_AxisRy_Knee_Flexion.STL" />
      </geometry>
      <material
        name="">
        <color
          rgba="0.752941176470588 0.752941176470588 0.752941176470588 1" />
      </material>
    </visual>
    <collision>
      <origin
        xyz="0 0 0"
        rpy="0 0 0" />
      <geometry>
        <mesh
          filename="package://CLOVIS25_URDF_V1/meshes/Link23_AxisRy_Knee_Flexion.STL" />
      </geometry>
    </collision>
  </link>
  <joint
    name="R23_AxisRy_Knee_Flexion"
    type="revolute">
    <origin
      xyz="0 0 0.0360000000000001"
      rpy="-3.14159265358979 0 0" />
    <parent
      link="Link22_AxisRz_Hips_Rotation" />
    <child
      link="Link23_AxisRy_Knee_Flexion" />
    <axis
      xyz="0 1 0" />
    <limit
      lower="0"
      upper="2.094"
      effort="3.66"
      velocity="5.05" />
  </joint>
  <link
    name="Link24_AxisRy_Ankle_Flexion">
    <inertial>
      <origin
        xyz="-4.88788155061531E-05 4.22890455320513E-07 -0.000941696318086993"
        rpy="0 0 0" />
      <mass
        value="0.0198828972990001" />
      <inertia
        ixx="5.33136120560905E-06"
        ixy="5.67486535153512E-11"
        ixz="-6.76121286353346E-09"
        iyy="3.84427570506982E-06"
        iyz="-4.03028590650372E-12"
        izz="8.29733412364016E-06" />
    </inertial>
    <visual>
      <origin
        xyz="0 0 0"
        rpy="0 0 0" />
      <geometry>
        <mesh
          filename="package://CLOVIS25_URDF_V1/meshes/Link24_AxisRy_Ankle_Flexion.STL" />
      </geometry>
      <material
        name="">
        <color
          rgba="0.752941176470588 0.752941176470588 0.752941176470588 1" />
      </material>
    </visual>
    <collision>
      <origin
        xyz="0 0 0"
        rpy="0 0 0" />
      <geometry>
        <mesh
          filename="package://CLOVIS25_URDF_V1/meshes/Link24_AxisRy_Ankle_Flexion.STL" />
      </geometry>
    </collision>
  </link>
  <joint
    name="R24_AxisRy_Ankle_Flexion"
    type="revolute">
    <origin
      xyz="0 0 -0.14"
      rpy="0 0 0" />
    <parent
      link="Link23_AxisRy_Knee_Flexion" />
    <child
      link="Link24_AxisRy_Ankle_Flexion" />
    <axis
      xyz="0 1 0" />
    <limit
      lower="-0.96"
      upper="0.689"
      effort="3.66"
      velocity="5.05" />
  </joint>
  <link
    name="Link25_AxisRx_Ankle_Abduction">
    <inertial>
      <origin
        xyz="-0.00749525839677809 -1.0018923289612E-07 -0.0413958069745799"
        rpy="0 0 0" />
      <mass
        value="0.162069791661843" />
      <inertia
        ixx="8.3758383186479E-05"
        ixy="9.35835759062825E-11"
        ixz="5.76979848237026E-06"
        iyy="0.000111745804626165"
        iyz="5.47634485662616E-10"
        izz="0.000127010438487016" />
    </inertial>
    <visual>
      <origin
        xyz="0 0 0"
        rpy="0 0 0" />
      <geometry>
        <mesh
          filename="package://CLOVIS25_URDF_V1/meshes/Link25_AxisRx_Ankle_Abduction.STL" />
      </geometry>
      <material
        name="">
        <color
          rgba="0.752941176470588 0.752941176470588 0.752941176470588 1" />
      </material>
    </visual>
    <collision>
      <origin
        xyz="0 0 0"
        rpy="0 0 0" />
      <geometry>
        <mesh
          filename="package://CLOVIS25_URDF_V1/meshes/Link25_AxisRx_Ankle_Abduction.STL" />
      </geometry>
    </collision>
  </link>
  <joint
    name="R25_AxisRx_Ankle_Abduction"
    type="revolute">
    <origin
      xyz="0 0 0"
      rpy="0 0 0" />
    <parent
      link="Link24_AxisRy_Ankle_Flexion" />
    <child
      link="Link25_AxisRx_Ankle_Abduction" />
    <axis
      xyz="1 0 0" />
    <limit
      lower="-0.96"
      upper="0.96"
      effort="3.66"
      velocity="5.05" />
  </joint>
  <link
    name="Link26_AxisRx_Toe_Flexion">
    <inertial>
      <origin
        xyz="0.0181977115240336 0.00126288994199178 -0.00954659053967744"
        rpy="0 0 0" />
      <mass
        value="0.066418983057976" />
      <inertia
        ixx="3.95754215658759E-05"
        ixy="-1.39838716866599E-06"
        ixz="4.60537840513909E-06"
        iyy="2.87049416190122E-05"
        iyz="-1.28510150088012E-07"
        izz="5.63529154046931E-05" />
    </inertial>
    <visual>
      <origin
        xyz="0 0 0"
        rpy="0 0 0" />
      <geometry>
        <mesh
          filename="package://CLOVIS25_URDF_V1/meshes/Link26_AxisRx_Toe_Flexion.STL" />
      </geometry>
      <material
        name="">
        <color
          rgba="0.752941176470588 0.752941176470588 0.752941176470588 1" />
      </material>
    </visual>
    <collision>
      <origin
        xyz="0 0 0"
        rpy="0 0 0" />
      <geometry>
        <mesh
          filename="package://CLOVIS25_URDF_V1/meshes/Link26_AxisRx_Toe_Flexion.STL" />
      </geometry>
    </collision>
  </link>
  <joint
    name="R26_AxisRx_Toe_Flexion"
    type="revolute">
    <origin
      xyz="0.0550000000000001 0 -0.0425"
      rpy="0 0 0" />
    <parent
      link="Link25_AxisRx_Ankle_Abduction" />
    <child
      link="Link26_AxisRx_Toe_Flexion" />
    <axis
      xyz="0 1 0" />
    <limit
      lower="-0.785"
      upper="0.96"
      effort="0.44"
      velocity="5.05" />
  </joint>
</robot>